Workbook

Sheet Overzicht
A1: Marge-overzicht offerte Ville de Mons – BO.F.2026/Signalétique int & ext/GC
A2: INTERN – niet bij de offerte voegen. Verkoopprijzen = ingediende offerte; aankoopprijzen = invullen uit Igepa (tab Materialen).
B4: Totaal verkoop excl. btw | C4: Verkoop posten met volledige kost | D4: Kost (volledige posten) | E4: Marge (volledige posten) | F4: Marge % | G4: Posten niet volledig
A5: Lot 1 | B5: ='Lot 1'!Z36 | C5: ='Lot 1'!Y36 | D5: ='Lot 1'!AA36 | E5: ='Lot 1'!AB36 | F5: =IF(C5=0,"",E5/C5) | G5: =COUNTIF('Lot 1'!AC2:AC34,"<>OK")
A6: Lot 2 | B6: ='Lot 2'!Z133 | C6: ='Lot 2'!Y133 | D6: ='Lot 2'!AA133 | E6: ='Lot 2'!AB133 | F6: =IF(C6=0,"",E6/C6) | G6: =COUNTIF('Lot 2'!AC2:AC131,"<>OK")
A7: Totaal | B7: =SUM(B5:B6) | C7: =SUM(C5:C6) | D7: =SUM(D5:D6) | E7: =SUM(E5:E6) | F7: =IF(C7=0,"",E7/C7) | G7: =SUM(G5:G6)
A10: Werkwijze:
A11: 1. Tab Materialen: per materiaal het Igepa-artikel kiezen, aankoopformaat, m² per rol/plaat en uw nettoprijs invullen (gele cellen).
A12: 2. Tab Instellingen: inktprijs/verbruik, afval % en intern uurtarief invullen.
A13: 3. Tabs Lot 1 / Lot 2: per post eventueel arbeidsminuten en overige kosten (hoogwerker, transport) invullen.
A14: 4. Kolom 'Marge %' kleurt rood onder de doelmarge, oranje tot +15 punten, groen daarboven.
A15: 5. 'Verkoop / m²' vs 'Aankoop mat. / m²' toont per post de factor tussen verkoop en materiaalprijs.
A16: Aannames om te controleren: verbruik in m² = nettoformaat × (1 + afval %); oogjes geteld volgens bestek (om de 30/50 cm);
A17: zomen, gaines en lasnaden niet apart in m² meegerekend; posten 22 (per 10) en 23 (per stuk) volgen de interpretatie uit de offerte.

Sheet Instellingen
A1: Instellingen kostprijsberekening (gele cellen = invullen)
A3: Afval % rolmedia (zeil, vinyl, textiel, film) | B3: 0.1 | C3: Aanname – aanpassen aan uw praktijk
A4: Afval % plaatmateriaal (Forex, Dibond, plexi, karton, biprint) | B4: 0.15 | C4: Aanname – hangt af van nesting op plaatformaat
A5: Latex-inkt: prijs per cartridge excl. btw | C5: Uit Igepa (bv. HP Latex 775 ml / 1 L)
A6: Latex-inkt: ml per cartridge | C6: bv. 775 of 1000
A7: Latex-inkt: verbruik ml per m² | C7: Uit uw RIP / printerlog, per printmodus
A8: Inktkost per m² (berekend) | B8: =IF(AND(B5>0,B6>0,B7>0),B5/B6*B7,0) | C8: prijs ÷ ml per cartridge × ml/m²
A9: Intern uurtarief (loonkost) excl. btw | C9: Voor de kolom arbeid in Lot 1 / Lot 2
A10: Doelmarge (ondergrens, voor kleurcode) | B10: 0.35 | C10: Rood onder deze marge

Sheet Materialen
A1: ID | B1: Materiaal (eis uit bestek) | C1: Zoekterm Igepa | D1: Type | E1: Bedrukt (J/N) | F1: Aankoopformaat (bv. rol 1,60 x 50 m / plaat 3,05 x 2,03 m) | G1: m² per aankoopeenheid (stukgoed: aantal stuks per verpakking) | H1: Aankoopprijs per eenheid excl. btw | I1: Aankoopprijs per m² / stuk | J1: Igepa artikelnr. | K1: Opmerking
A2: M01 | B2: Backlit PVC-zeil 650 g/m², M2/B1 (backlight 3x4 m) | C2: backlit 650 / Blockout backlit | D2: rol | E2: J | I2: =IF(AND(G2>0,H2>0),H2/G2,"")
A3: M02 | B3: Frontlit PVC-zeil 450 g/m² (kakémono entrées, Warocqué, bas rue Neuve, bannière) | C3: frontlit 450 | D3: rol | E3: J | I3: =IF(AND(G3>0,H3>0),H3/G3,"")
A4: M03 | B4: PVC-zeil 550 g/m² 'pro' (Duesberg, cube VisitMons) | C4: frontlit 510/550 | D4: rol | E4: J | I4: =IF(AND(G4>0,H4>0),H4/G4,"")
A5: M04 | B5: Mesh micro-geperforeerd 450 g/m² (kakémono Imagix) | C5: mesh 450 / mesh backlit | D5: rol | E5: J | I5: =IF(AND(G5>0,H5>0),H5/G5,"")
A6: M05 | B6: Mesh 350 g/m² (bâche travaux) | C6: mesh 350 | D6: rol | E6: J | I6: =IF(AND(G6>0,H6>0),H6/G6,"")
A7: M06 | B7: Mesh micro-geperforeerd 290 g/m² (Heras, Nadar) | C7: mesh 270/290 | D7: rol | E7: J | I7: =IF(AND(G7>0,H7>0),H7/G7,"")
A8: M07 | B8: PVC-zeil 330 g/m² (bâches cubes) | C8: frontlit 340 / light | D8: rol | E8: J | I8: =IF(AND(G8>0,H8>0),H8/G8,"")
A9: M10 | B9: Roll-up film (PET/PP greyback, anti-curl) | C9: roll-up film | D9: rol | E9: J | I9: =IF(AND(G9>0,H9>0),H9/G9,"")
A10: M11 | B10: Roll-up cassette 85 x 200 cm + tas | C10: roll-up 85 | D10: stuk | E10: N | G10: 1 | I10: =IF(AND(G10>0,H10>0),H10/G10,"")
A11: M12 | B11: Roll-up cassette 60 x 160 cm + tas | C11: roll-up 60 | D11: stuk | E11: N | G11: 1 | I11: =IF(AND(G11>0,H11>0),H11/G11,"")
A12: M13 | B12: Elektrostatische folie (type Yupo Tako / static cling) | C12: static cling / Yupo Tako | D12: rol | E12: J | I12: =IF(AND(G12>0,H12>0),H12/G12,"")
A13: M14 | B13: Polymeer vinyl transparant glanzend (Prix Mercure, wit onderdruk) | C13: polymeer transparant glans | D13: rol | E13: J | I13: =IF(AND(G13>0,H13>0),H13/G13,"")
A14: M15 | B14: Monomeer vinyl wit (stickers, vitrine, totem, Lot 2 vinyl binnen) | C14: monomeer wit glans/mat | D14: rol | E14: J | I14: =IF(AND(G14>0,H14>0),H14/G14,"")
A15: M16 | B15: One-way vision / micro-geperforeerd raamvinyl (voertuig) | C15: one way vision | D15: rol | E15: J | I15: =IF(AND(G15>0,H15>0),H15/G15,"")
A16: M17 | B16: Cast/polymeer wrapfolie carrosserie (+ evt. laminaat) | C16: cast wrap / polymeer | D16: rol | E16: J | I16: =IF(AND(G16>0,H16>0),H16/G16,"")
A17: M18 | B17: Polymeer vinyl buiten | C17: polymeer wit | D17: rol | E17: J | I17: =IF(AND(G17>0,H17>0),H17/G17,"")
A18: M19 | B18: Laminaat monomeer glanzend (totem) | C18: laminaat monomeer glans | D18: rol | E18: N | I18: =IF(AND(G18>0,H18>0),H18/G18,"")
A19: M20 | B19: Beachflag-textiel polyester knit ±110 g/m² | C19: flag 110 / vlaggendoek | D19: rol | E19: J | I19: =IF(AND(G19>0,H19>0),H19/G19,"")
A20: M21 | B20: Beachflag-kit: alu mast 350 cm, horizontale arm, kruisvoet, tas | C20: beachflag kit | D20: stuk | E20: N | G20: 1 | I20: =IF(AND(G20>0,H20>0),H20/G20,"")
A21: M22 | B21: Biprint / PP-alveolair 3 mm | C21: biprint 3 mm | D21: plaat | E21: J | I21: =IF(AND(G21>0,H21>0),H21/G21,"")
A22: M23 | B22: Akylux / PP-alveolair (3,5 mm? bestek: '3,5 cm' – te verifiëren) | C22: akylux | D22: plaat | E22: J | I22: =IF(AND(G22>0,H22>0),H22/G22,"")
A23: M24 | B23: Balelastiek 5 mm, 15 cm | C23: balelastiek | D23: stuk | E23: N | G23: 1 | I23: =IF(AND(G23>0,H23>0),H23/G23,"")
A24: M25 | B24: Metalen oogjes (per stuk, incl. ring) | C24: oogjes / zeilringen | D24: stuk | E24: N | G24: 1 | I24: =IF(AND(G24>0,H24>0),H24/G24,"")
A25: M26 | B25: Ophangsysteem / klemlijsten op maat (backlight) | C25: klemprofiel / spieprofiel | D25: stuk | E25: N | G25: 1 | I25: =IF(AND(G25>0,H25>0),H25/G25,"")
A26: M30 | B26: Polyester textiel 300 g/m² wit M1, wandkleefbaar | C26: textiel 300 M1 / wallpaper textile | D26: rol | E26: J | I26: =IF(AND(G26>0,H26>0),H26/G26,"")
A27: M31 | B27: Forex (PVC-hardschuim) 2 mm wit | C27: forex 2 mm | D27: plaat | E27: J | I27: =IF(AND(G27>0,H27>0),H27/G27,"")
A28: M32 | B28: Forex 3 mm wit | C28: forex 3 mm | D28: plaat | E28: J | I28: =IF(AND(G28>0,H28>0),H28/G28,"")
A29: M33 | B29: Forex 5 mm wit | C29: forex 5 mm | D29: plaat | E29: J | I29: =IF(AND(G29>0,H29>0),H29/G29,"")
A30: M34 | B30: Plexi (PMMA) opaal mat 2 mm | C30: plexi opaal 2 mm | D30: plaat | E30: J | I30: =IF(AND(G30>0,H30>0),H30/G30,"")
A31: M35 | B31: Plexi (PMMA) opaal mat 3 mm | C31: plexi opaal 3 mm | D31: plaat | E31: J | I31: =IF(AND(G31>0,H31>0),H31/G31,"")
A32: M36 | B32: Karton 2 mm (bedrukbaar) | C32: karton 2 mm / honingraat / reboard | D32: plaat | E32: J | I32: =IF(AND(G32>0,H32>0),H32/G32,"")
A33: M37 | B33: Karton 1 mm (bedrukbaar) | C33: karton 1 mm | D33: plaat | E33: J | I33: =IF(AND(G33>0,H33>0),H33/G33,"")
A34: M39 | B34: Dibond / alu-composiet 2 mm wit | C34: dibond 2 mm | D34: plaat | E34: J | I34: =IF(AND(G34>0,H34>0),H34/G34,"")
A35: M40 | B35: Dibond / alu-composiet 3 mm wit | C35: dibond 3 mm | D35: plaat | E35: J | I35: =IF(AND(G35>0,H35>0),H35/G35,"")
A36: M41 | B36: Snijvinyl gekleurd/zwart (type Oracal 641/651) | C36: snijfolie / plotterfolie | D36: rol | E36: N | I36: =IF(AND(G36>0,H36>0),H36/G36,"")
A37: M42 | B37: Applicatietape (transfer) | C37: applicatietape | D37: rol | E37: N | I37: =IF(AND(G37>0,H37>0),H37/G37,"")
A38: M43 | B38: Dubbelzijdige tape wandmontage (per lopende meter) | C38: dubbelzijdig montagetape | D38: stuk | E38: N | G38: 1 | I38: =IF(AND(G38>0,H38>0),H38/G38,"")
A39: M44 | B39: Metalen U-profiel / ophanglat (per stuk) | C39: U-profiel / ophangprofiel | D39: stuk | E39: N | G39: 1 | I39: =IF(AND(G39>0,H39>0),H39/G39,"")

Sheet Lot 1
A1: N° | B1: Rubriek | C1: Omschrijving | D1: Eenheid | E1: Q | F1: Verkoop PU excl. btw | G1: Materiaal 1 | H1: m² mat. 1 / eenheid | I1: Materiaal 2 | J1: m² mat. 2 / eenheid | K1: Acc. 1 | L1: Aantal acc. 1 | M1: Acc. 2 | N1: Aantal acc. 2 | O1: Afval % | P1: Materiaalkost / eenheid | Q1: Inktkost / eenheid | R1: Arbeid min / eenheid | S1: Arbeid € / eenheid | T1: Overige kost / eenheid (huur, transport) | U1: Kostprijs / eenheid | V1: Marge € / eenheid | W1: Marge % | X1: Verkoop / m² | Y1: Aankoop mat. / m² | Z1: Totaal verkoop | AA1: Totaal kost | AB1: Totaal marge | AC1: Controle | AD1: Opmerking
A2: 1 | B2: BÂCHE BACKLIGHT | C2: Format 3x4m (format utile 280x380cm) - Bâche rétroéclairée M2 de 650gr - Quadrichromie - attaches par réglette sur mesure | D2: pièce | E2: 20 | F2: 225 | G2: M01 | H2: 12 | K2: M26 | L2: 1 | O2: =IF(G2="","",IF(IFERROR(VLOOKUP(G2,Materialen!$A$2:$I$39,4,0),"")="plaat",Instellingen!$B$4,Instellingen!$B$3)) | P2: =ROUND(N(H2)*IFERROR(IF(VLOOKUP(G2,Materialen!$A$2:$I$39,9,0)="",0,VLOOKUP(G2,Materialen!$A$2:$I$39,9,0)),0)*(1+N(O2))+N(J2)*IFERROR(IF(VLOOKUP(I2,Materialen!$A$2:$I$39,9,0)="",0,VLOOKUP(I2,Materialen!$A$2:$I$39,9,0)),0)*(1+N(O2))+N(L2)*IFERROR(IF(VLOOKUP(K2,Materialen!$A$2:$I$39,9,0)="",0,VLOOKUP(K2,Materialen!$A$2:$I$39,9,0)),0)+N(N2)*IFERROR(IF(VLOOKUP(M2,Materialen!$A$2:$I$39,9,0)="",0,VLOOKUP(M2,Materialen!$A$2:$I$39,9,0)),0),2) | Q2: =IF(G2="",0,IF(IFERROR(VLOOKUP(G2,Materialen!$A$2:$I$39,5,0),"N")="J",ROUND(N(H2)*(1+N(O2))*Instellingen!$B$8,2),0)) | S2: =ROUND(N(R2)/60*Instellingen!$B$9,2) | U2: =P2+Q2+S2+N(T2) | V2: =IF(AC2<>"OK","",F2-U2) | W2: =IF(OR(F2=0,AC2<>"OK"),"",V2/F2) | X2: =IF(N(H2)>0,F2/H2,"") | Y2: =IF(N(H2)>0,IFERROR(IF(VLOOKUP(G2,Materialen!$A$2:$I$39,9,0)="",0,VLOOKUP(G2,Materialen!$A$2:$I$39,9,0)),0),"") | Z2: =ROUND(E2*F2,2) | AA2: =IF(AC2<>"OK","",ROUND(E2*U2,2)) | AB2: =IF(AC2<>"OK","",Z2-AA2) | AC2: =IF((IF(G2="",0,IF(IFERROR(IF(VLOOKUP(G2,Materialen!$A$2:$I$39,9,0)="",0,VLOOKUP(G2,Materialen!$A$2:$I$39,9,0)),0)=0,1,0))+IF(I2="",0,IF(IFERROR(IF(VLOOKUP(I2,Materialen!$A$2:$I$39,9,0)="",0,VLOOKUP(I2,Materialen!$A$2:$I$39,9,0)),0)=0,1,0))+IF(K2="",0,IF(IFERROR(IF(VLOOKUP(K2,Materialen!$A$2:$I$39,9,0)="",0,VLOOKUP(K2,Materialen!$A$2:$I$39,9,0)),0)=0,1,0))+IF(M2="",0,IF(IFERROR(IF(VLOOKUP(M2,Materialen!$A$2:$I$39,9,0)="",0,VLOOKUP(M2,Materialen!$A$2:$I$39,9,0)),0)=0,1,0)))>0,"aankoopprijs ontbreekt",IF(AND(G2="",K2="",N(T2)=0,N(R2)=0),"kost invullen (arbeid/overig)","OK")) | AD2: Drukformaat 3x4 m
A3: 2 | B3: BÂCHE BACKLIGHT | C3: Placement de la bâche sur place (8, rue neuve) à l'aide d'un élévateur (8, rue neuve) | D3: placement | E3: 20 | F3: 165 | O3: =IF(G3="","",IF(IFERROR(VLOOKUP(G3,Materialen!$A$2:$I$39,4,0),"")="plaat",Instellingen!$B$4,Instellingen!$B$3)) | P3: =ROUND(N(H3)*IFERROR(IF(VLOOKUP(G3,Materialen!$A$2:$I$39,9,0)="",0,VLOOKUP(G3,Materialen!$A$2:$I$39,9,0)),0)*(1+N(O3))+N(J3)*IFERROR(IF(VLOOKUP(I3,Materialen!$A$2:$I$39,9,0)="",0,VLOOKUP(I3,Materialen!$A$2:$I$39,9,0)),0)*(1+N(O3))+N(L3)*IFERROR(IF(VLOOKUP(K3,Materialen!$A$2:$I$39,9,0)="",0,VLOOKUP(K3,Materialen!$A$2:$I$39,9,0)),0)+N(N3)*IFERROR(IF(VLOOKUP(M3,Materialen!$A$2:$I$39,9,0)="",0,VLOOKUP(M3,Materialen!$A$2:$I$39,9,0)),0),2) | Q3: =IF(G3="",0,IF(IFERROR(VLOOKUP(G3,Materialen!$A$2:$I$39,5,0),"N")="J",ROUND(N(H3)*(1+N(O3))*Instellingen!$B$8,2),0)) | S3: =ROUND(N(R3)/60*Instellingen!$B$9,2) | U3: =P3+Q3+S3+N(T3) | V3: =IF(AC3<>"OK","",F3-U3) | W3: =IF(OR(F3=0,AC3<>"OK"),"",V3/F3) | X3: =IF(N(H3)>0,F3/H3,"") | Y3: =IF(N(H3)>0,IFERROR(IF(VLOOKUP(G3,Materialen!$A$2:$I$39,9,0)="",0,VLOOKUP(G3,Materialen!$A$2:$I$39,9,0)),0),"") | Z3: =ROUND(E3*F3,2) | AA3: =IF(AC3<>"OK","",ROUND(E3*U3,2)) | AB3: =IF(AC3<>"OK","",Z3-AA3) | AC3: =IF((IF(G3="",0,IF(IFERROR(IF(VLOOKUP(G3,Materialen!$A$2:$I$39,9,0)="",0,VLOOKUP(G3,Materialen!$A$2:$I$39,9,0)),0)=0,1,0))+IF(I3="",0,IF(IFERROR(IF(VLOOKUP(I3,Materialen!$A$2:$I$39,9,0)="",0,VLOOKUP(I3,Materialen!$A$2:$I$39,9,0)),0)=0,1,0))+IF(K3="",0,IF(IFERROR(IF(VLOOKUP(K3,Materialen!$A$2:$I$39,9,0)="",0,VLOOKUP(K3,Materialen!$A$2:$I$39,9,0)),0)=0,1,0))+IF(M3="",0,IF(IFERROR(IF(VLOOKUP(M3,Materialen!$A$2:$I$39,9,0)="",0,VLOOKUP(M3,Materialen!$A$2:$I$39,9,0)),0)=0,1,0)))>0,"aankoopprijs ontbreekt",IF(AND(G3="",K3="",N(T3)=0,N(R3)=0),"kost invullen (arbeid/overig)","OK")) | AD3: Hoogwerker + plaatsing → kolom 'overige kost' en arbeid
A4: 3 | B4: KAKEMONOS | C4: Musée Duesberg : H 251 cm x 79 cm - impression quadri recto / verso - ourlet supérieur et inférieur | D4: pièce | E4: 10 | F4: 48 | G4: M03 | H4: 1.9829 | O4: =IF(G4="","",IF(IFERROR(VLOOKUP(G4,Materialen!$A$2:$I$39,4,0),"")="plaat",Instellingen!$B$4,Instellingen!$B$3)) | P4: =ROUND(N(H4)*IFERROR(IF(VLOOKUP(G4,Materialen!$A$2:$I$39,9,0)="",0,VLOOKUP(G4,Materialen!$A$2:$I$39,9,0)),0)*(1+N(O4))+N(J4)*IFERROR(IF(VLOOKUP(I4,Materialen!$A$2:$I$39,9,0)="",0,VLOOKUP(I4,Materialen!$A$2:$I$39,9,0)),0)*(1+N(O4))+N(L4)*IFERROR(IF(VLOOKUP(K4,Materialen!$A$2:$I$39,9,0)="",0,VLOOKUP(K4,Materialen!$A$2:$I$39,9,0)),0)+N(N4)*IFERROR(IF(VLOOKUP(M4,Materialen!$A$2:$I$39,9,0)="",0,VLOOKUP(M4,Materialen!$A$2:$I$39,9,0)),0),2) | Q4: =IF(G4="",0,IF(IFERROR(VLOOKUP(G4,Materialen!$A$2:$I$39,5,0),"N")="J",ROUND(N(H4)*(1+N(O4))*Instellingen!$B$8,2),0)) | S4: =ROUND(N(R4)/60*Instellingen!$B$9,2) | U4: =P4+Q4+S4+N(T4) | V4: =IF(AC4<>"OK","",F4-U4) | W4: =IF(OR(F4=0,AC4<>"OK"),"",V4/F4) | X4: =IF(N(H4)>0,F4/H4,"") | Y4: =IF(N(H4)>0,IFERROR(IF(VLOOKUP(G4,Materialen!$A$2:$I$39,9,0)="",0,VLOOKUP(G4,Materialen!$A$2:$I$39,9,0)),0),"") | Z4: =ROUND(E4*F4,2) | AA4: =IF(AC4<>"OK","",ROUND(E4*U4,2)) | AB4: =IF(AC4<>"OK","",Z4-AA4) | AC4: =IF((IF(G4="",0,IF(IFERROR(IF(VLOOKUP(G4,Materialen!$A$2:$I$39,9,0)="",0,VLOOKUP(G4,Materialen!$A$2:$I$39,9,0)),0)=0,1,0))+IF(I4="",0,IF(IFERROR(IF(VLOOKUP(I4,Materialen!$A$2:$I$39,9,0)="",0,VLOOKUP(I4,Materialen!$A$2:$I$39,9,0)),0)=0,1,0))+IF(K4="",0,IF(IFERROR(IF(VLOOKUP(K4,Materialen!$A$2:$I$39,9,0)="",0,VLOOKUP(K4,Materialen!$A$2:$I$39,9,0)),0)=0,1,0))+IF(M4="",0,IF(IFERROR(IF(VLOOKUP(M4,Materialen!$A$2:$I$39,9,0)="",0,VLOOKUP(M4,Materialen!$A$2:$I$39,9,0)),0)=0,1,0)))>0,"aankoopprijs ontbreekt",IF(AND(G4="",K4="",N(T4)=0,N(R4)=0),"kost invullen (arbeid/overig)","OK"))
A5: 4 | B5: KAKEMONOS | C5: Entrées de ville : Format L100 x H300 cm - bâche sur Frontlit 450 gr quadri recto UV, avec gaines cousues haut et bas de 8 cm à plat | D5: pièce | E5: 130 | F5: 49 | G5: M02 | H5: 3 | O5: =IF(G5="","",IF(IFERROR(VLOOKUP(G5,Materialen!$A$2:$I$39,4,0),"")="plaat",Instellingen!$B$4,Instellingen!$B$3)) | P5: =ROUND(N(H5)*IFERROR(IF(VLOOKUP(G5,Materialen!$A$2:$I$39,9,0)="",0,VLOOKUP(G5,Materialen!$A$2:$I$39,9,0)),0)*(1+N(O5))+N(J5)*IFERROR(IF(VLOOKUP(I5,Materialen!$A$2:$I$39,9,0)="",0,VLOOKUP(I5,Materialen!$A$2:$I$39,9,0)),0)*(1+N(O5))+N(L5)*IFERROR(IF(VLOOKUP(K5,Materialen!$A$2:$I$39,9,0)="",0,VLOOKUP(K5,Materialen!$A$2:$I$39,9,0)),0)+N(N5)*IFERROR(IF(VLOOKUP(M5,Materialen!$A$2:$I$39,9,0)="",0,VLOOKUP(M5,Materialen!$A$2:$I$39,9,0)),0),2) | Q5: =IF(G5="",0,IF(IFERROR(VLOOKUP(G5,Materialen!$A$2:$I$39,5,0),"N")="J",ROUND(N(H5)*(1+N(O5))*Instellingen!$B$8,2),0)) | S5: =ROUND(N(R5)/60*Instellingen!$B$9,2) | U5: =P5+Q5+S5+N(T5) | V5: =IF(AC5<>"OK","",F5-U5) | W5: =IF(OR(F5=0,AC5<>"OK"),"",V5/F5) | X5: =IF(N(H5)>0,F5/H5,"") | Y5: =IF(N(H5)>0,IFERROR(IF(VLOOKUP(G5,Materialen!$A$2:$I$39,9,0)="",0,VLOOKUP(G5,Materialen!$A$2:$I$39,9,0)),0),"") | Z5: =ROUND(E5*F5,2) | AA5: =IF(AC5<>"OK","",ROUND(E5*U5,2)) | AB5: =IF(AC5<>"OK","",Z5-AA5) | AC5: =IF((IF(G5="",0,IF(IFERROR(IF(VLOOKUP(G5,Materialen!$A$2:$I$39,9,0)="",0,VLOOKUP(G5,Materialen!$A$2:$I$39,9,0)),0)=0,1,0))+IF(I5="",0,IF(IFERROR(IF(VLOOKUP(I5,Materialen!$A$2:$I$39,9,0)="",0,VLOOKUP(I5,Materialen!$A$2:$I$39,9,0)),0)=0,1,0))+IF(K5="",0,IF(IFERROR(IF(VLOOKUP(K5,Materialen!$A$2:$I$39,9,0)="",0,VLOOKUP(K5,Materialen!$A$2:$I$39,9,0)),0)=0,1,0))+IF(M5="",0,IF(IFERROR(IF(VLOOKUP(M5,Materialen!$A$2:$I$39,9,0)="",0,VLOOKUP(M5,Materialen!$A$2:$I$39,9,0)),0)=0,1,0)))>0,"aankoopprijs ontbreekt",IF(AND(G5="",K5="",N(T5)=0,N(R5)=0),"kost invullen (arbeid/overig)","OK")) | AD5: Gaines 8 cm: + stof voor zomen niet meegeteld
A6: 5 | B6: KAKEMONOS | C6: Imagix: Format L150 x H450 cm - bâche micro-perforée 450 gr quadri recto UV, avec gaines cousues haut et bas de 8 cm à plat | D6: pièce | E6: 35 | F6: 110 | G6: M04 | H6: 6.75 | O6: =IF(G6="","",IF(IFERROR(VLOOKUP(G6,Materialen!$A$2:$I$39,4,0),"")="plaat",Instellingen!$B$4,Instellingen!$B$3)) | P6: =ROUND(N(H6)*IFERROR(IF(VLOOKUP(G6,Materialen!$A$2:$I$39,9,0)="",0,VLOOKUP(G6,Materialen!$A$2:$I$39,9,0)),0)*(1+N(O6))+N(J6)*IFERROR(IF(VLOOKUP(I6,Materialen!$A$2:$I$39,9,0)="",0,VLOOKUP(I6,Materialen!$A$2:$I$39,9,0)),0)*(1+N(O6))+N(L6)*IFERROR(IF(VLOOKUP(K6,Materialen!$A$2:$I$39,9,0)="",0,VLOOKUP(K6,Materialen!$A$2:$I$39,9,0)),0)+N(N6)*IFERROR(IF(VLOOKUP(M6,Materialen!$A$2:$I$39,9,0)="",0,VLOOKUP(M6,Materialen!$A$2:$I$39,9,0)),0),2) | Q6: =IF(G6="",0,IF(IFERROR(VLOOKUP(G6,Materialen!$A$2:$I$39,5,0),"N")="J",ROUND(N(H6)*(1+N(O6))*Instellingen!$B$8,2),0)) | S6: =ROUND(N(R6)/60*Instellingen!$B$9,2) | U6: =P6+Q6+S6+N(T6) | V6: =IF(AC6<>"OK","",F6-U6) | W6: =IF(OR(F6=0,AC6<>"OK"),"",V6/F6) | X6: =IF(N(H6)>0,F6/H6,"") | Y6: =IF(N(H6)>0,IFERROR(IF(VLOOKUP(G6,Materialen!$A$2:$I$39,9,0)="",0,VLOOKUP(G6,Materialen!$A$2:$I$39,9,0)),0),"") | Z6: =ROUND(E6*F6,2) | AA6: =IF(AC6<>"OK","",ROUND(E6*U6,2)) | AB6: =IF(AC6<>"OK","",Z6-AA6) | AC6: =IF((IF(G6="",0,IF(IFERROR(IF(VLOOKUP(G6,Materialen!$A$2:$I$39,9,0)="",0,VLOOKUP(G6,Materialen!$A$2:$I$39,9,0)),0)=0,1,0))+IF(I6="",0,IF(IFERROR(IF(VLOOKUP(I6,Materialen!$A$2:$I$39,9,0)="",0,VLOOKUP(I6,Materialen!$A$2:$I$39,9,0)),0)=0,1,0))+IF(K6="",0,IF(IFERROR(IF(VLOOKUP(K6,Materialen!$A$2:$I$39,9,0)="",0,VLOOKUP(K6,Materialen!$A$2:$I$39,9,0)),0)=0,1,0))+IF(M6="",0,IF(IFERROR(IF(VLOOKUP(M6,Materialen!$A$2:$I$39,9,0)="",0,VLOOKUP(M6,Materialen!$A$2:$I$39,9,0)),0)=0,1,0)))>0,"aankoopprijs ontbreekt",IF(AND(G6="",K6="",N(T6)=0,N(R6)=0),"kost invullen (arbeid/overig)","OK"))
A7: 6 | B7: BÂCHE | C7: Bâche travaux: Bâche microperforée mesh 350gr/m² Format L 280cm x H 380cm Impression digital quadricouleur Finition doublure + œillets métalliques tous les 50cm | D7: pièce | E7: 20 | F7: 130 | G7: M05 | H7: 10.64 | K7: M25 | L7: 27 | O7: =IF(G7="","",IF(IFERROR(VLOOKUP(G7,Materialen!$A$2:$I$39,4,0),"")="plaat",Instellingen!$B$4,Instellingen!$B$3)) | P7: =ROUND(N(H7)*IFERROR(IF(VLOOKUP(G7,Materialen!$A$2:$I$39,9,0)="",0,VLOOKUP(G7,Materialen!$A$2:$I$39,9,0)),0)*(1+N(O7))+N(J7)*IFERROR(IF(VLOOKUP(I7,Materialen!$A$2:$I$39,9,0)="",0,VLOOKUP(I7,Materialen!$A$2:$I$39,9,0)),0)*(1+N(O7))+N(L7)*IFERROR(IF(VLOOKUP(K7,Materialen!$A$2:$I$39,9,0)="",0,VLOOKUP(K7,Materialen!$A$2:$I$39,9,0)),0)+N(N7)*IFERROR(IF(VLOOKUP(M7,Materialen!$A$2:$I$39,9,0)="",0,VLOOKUP(M7,Materialen!$A$2:$I$39,9,0)),0),2) | Q7: =IF(G7="",0,IF(IFERROR(VLOOKUP(G7,Materialen!$A$2:$I$39,5,0),"N")="J",ROUND(N(H7)*(1+N(O7))*Instellingen!$B$8,2),0)) | S7: =ROUND(N(R7)/60*Instellingen!$B$9,2) | U7: =P7+Q7+S7+N(T7) | V7: =IF(AC7<>"OK","",F7-U7) | W7: =IF(OR(F7=0,AC7<>"OK"),"",V7/F7) | X7: =IF(N(H7)>0,F7/H7,"") | Y7: =IF(N(H7)>0,IFERROR(IF(VLOOKUP(G7,Materialen!$A$2:$I$39,9,0)="",0,VLOOKUP(G7,Materialen!$A$2:$I$39,9,0)),0),"") | Z7: =ROUND(E7*F7,2) | AA7: =IF(AC7<>"OK","",ROUND(E7*U7,2)) | AB7: =IF(AC7<>"OK","",Z7-AA7) | AC7: =IF((IF(G7="",0,IF(IFERROR(IF(VLOOKUP(G7,Materialen!$A$2:$I$39,9,0)="",0,VLOOKUP(G7,Materialen!$A$2:$I$39,9,0)),0)=0,1,0))+IF(I7="",0,IF(IFERROR(IF(VLOOKUP(I7,Materialen!$A$2:$I$39,9,0)="",0,VLOOKUP(I7,Materialen!$A$2:$I$39,9,0)),0)=0,1,0))+IF(K7="",0,IF(IFERROR(IF(VLOOKUP(K7,Materialen!$A$2:$I$39,9,0)="",0,VLOOKUP(K7,Materialen!$A$2:$I$39,9,0)),0)=0,1,0))+IF(M7="",0,IF(IFERROR(IF(VLOOKUP(M7,Materialen!$A$2:$I$39,9,0)="",0,VLOOKUP(M7,Materialen!$A$2:$I$39,9,0)),0)=0,1,0)))>0,"aankoopprijs ontbreekt",IF(AND(G7="",K7="",N(T7)=0,N(R7)=0),"kost invullen (arbeid/overig)","OK")) | AD7: Oogjes om de 50 cm
A8: 7 | B8: BÂCHE | C8: Bâche barrières HERAS : Bâche micro perforée290gr format H 1,7 m x 3,4 m impression quadri finition doublure + œillets métalliques tous les 50 cm | D8: pièce | E8: 30 | F8: 70 | G8: M06 | H8: 5.78 | K8: M25 | L8: 21 | O8: =IF(G8="","",IF(IFERROR(VLOOKUP(G8,Materialen!$A$2:$I$39,4,0),"")="plaat",Instellingen!$B$4,Instellingen!$B$3)) | P8: =ROUND(N(H8)*IFERROR(IF(VLOOKUP(G8,Materialen!$A$2:$I$39,9,0)="",0,VLOOKUP(G8,Materialen!$A$2:$I$39,9,0)),0)*(1+N(O8))+N(J8)*IFERROR(IF(VLOOKUP(I8,Materialen!$A$2:$I$39,9,0)="",0,VLOOKUP(I8,Materialen!$A$2:$I$39,9,0)),0)*(1+N(O8))+N(L8)*IFERROR(IF(VLOOKUP(K8,Materialen!$A$2:$I$39,9,0)="",0,VLOOKUP(K8,Materialen!$A$2:$I$39,9,0)),0)+N(N8)*IFERROR(IF(VLOOKUP(M8,Materialen!$A$2:$I$39,9,0)="",0,VLOOKUP(M8,Materialen!$A$2:$I$39,9,0)),0),2) | Q8: =IF(G8="",0,IF(IFERROR(VLOOKUP(G8,Materialen!$A$2:$I$39,5,0),"N")="J",ROUND(N(H8)*(1+N(O8))*Instellingen!$B$8,2),0)) | S8: =ROUND(N(R8)/60*Instellingen!$B$9,2) | U8: =P8+Q8+S8+N(T8) | V8: =IF(AC8<>"OK","",F8-U8) | W8: =IF(OR(F8=0,AC8<>"OK"),"",V8/F8) | X8: =IF(N(H8)>0,F8/H8,"") | Y8: =IF(N(H8)>0,IFERROR(IF(VLOOKUP(G8,Materialen!$A$2:$I$39,9,0)="",0,VLOOKUP(G8,Materialen!$A$2:$I$39,9,0)),0),"") | Z8: =ROUND(E8*F8,2) | AA8: =IF(AC8<>"OK","",ROUND(E8*U8,2)) | AB8: =IF(AC8<>"OK","",Z8-AA8) | AC8: =IF((IF(G8="",0,IF(IFERROR(IF(VLOOKUP(G8,Materialen!$A$2:$I$39,9,0)="",0,VLOOKUP(G8,Materialen!$A$2:$I$39,9,0)),0)=0,1,0))+IF(I8="",0,IF(IFERROR(IF(VLOOKUP(I8,Materialen!$A$2:$I$39,9,0)="",0,VLOOKUP(I8,Materialen!$A$2:$I$39,9,0)),0)=0,1,0))+IF(K8="",0,IF(IFERROR(IF(VLOOKUP(K8,Materialen!$A$2:$I$39,9,0)="",0,VLOOKUP(K8,Materialen!$A$2:$I$39,9,0)),0)=0,1,0))+IF(M8="",0,IF(IFERROR(IF(VLOOKUP(M8,Materialen!$A$2:$I$39,9,0)="",0,VLOOKUP(M8,Materialen!$A$2:$I$39,9,0)),0)=0,1,0)))>0,"aankoopprijs ontbreekt",IF(AND(G8="",K8="",N(T8)=0,N(R8)=0),"kost invullen (arbeid/overig)","OK")) | AD8: Oogjes om de 50 cm
A9: 8 | B9: BÂCHE | C9: Bâche bas de la rue Neuve: H380 x L260 cm, avec œillets tous les 30 cm et élastiques, impression en quadrichromie | D9: pièce | E9: 10 | F9: 115 | G9: M02 | H9: 9.88 | K9: M25 | L9: 43 | M9: M24 | N9: 43 | O9: =IF(G9="","",IF(IFERROR(VLOOKUP(G9,Materialen!$A$2:$I$39,4,0),"")="plaat",Instellingen!$B$4,Instellingen!$B$3)) | P9: =ROUND(N(H9)*IFERROR(IF(VLOOKUP(G9,Materialen!$A$2:$I$39,9,0)="",0,VLOOKUP(G9,Materialen!$A$2:$I$39,9,0)),0)*(1+N(O9))+N(J9)*IFERROR(IF(VLOOKUP(I9,Materialen!$A$2:$I$39,9,0)="",0,VLOOKUP(I9,Materialen!$A$2:$I$39,9,0)),0)*(1+N(O9))+N(L9)*IFERROR(IF(VLOOKUP(K9,Materialen!$A$2:$I$39,9,0)="",0,VLOOKUP(K9,Materialen!$A$2:$I$39,9,0)),0)+N(N9)*IFERROR(IF(VLOOKUP(M9,Materialen!$A$2:$I$39,9,0)="",0,VLOOKUP(M9,Materialen!$A$2:$I$39,9,0)),0),2) | Q9: =IF(G9="",0,IF(IFERROR(VLOOKUP(G9,Materialen!$A$2:$I$39,5,0),"N")="J",ROUND(N(H9)*(1+N(O9))*Instellingen!$B$8,2),0)) | S9: =ROUND(N(R9)/60*Instellingen!$B$9,2) | U9: =P9+Q9+S9+N(T9) | V9: =IF(AC9<>"OK","",F9-U9) | W9: =IF(OR(F9=0,AC9<>"OK"),"",V9/F9) | X9: =IF(N(H9)>0,F9/H9,"") | Y9: =IF(N(H9)>0,IFERROR(IF(VLOOKUP(G9,Materialen!$A$2:$I$39,9,0)="",0,VLOOKUP(G9,Materialen!$A$2:$I$39,9,0)),0),"") | Z9: =ROUND(E9*F9,2) | AA9: =IF(AC9<>"OK","",ROUND(E9*U9,2)) | AB9: =IF(AC9<>"OK","",Z9-AA9) | AC9: =IF((IF(G9="",0,IF(IFERROR(IF(VLOOKUP(G9,Materialen!$A$2:$I$39,9,0)="",0,VLOOKUP(G9,Materialen!$A$2:$I$39,9,0)),0)=0,1,0))+IF(I9="",0,IF(IFERROR(IF(VLOOKUP(I9,Materialen!$A$2:$I$39,9,0)="",0,VLOOKUP(I9,Materialen!$A$2:$I$39,9,0)),0)=0,1,0))+IF(K9="",0,IF(IFERROR(IF(VLOOKUP(K9,Materialen!$A$2:$I$39,9,0)="",0,VLOOKUP(K9,Materialen!$A$2:$I$39,9,0)),0)=0,1,0))+IF(M9="",0,IF(IFERROR(IF(VLOOKUP(M9,Materialen!$A$2:$I$39,9,0)="",0,VLOOKUP(M9,Materialen!$A$2:$I$39,9,0)),0)=0,1,0)))>0,"aankoopprijs ontbreekt",IF(AND(G9="",K9="",N(T9)=0,N(R9)=0),"kost invullen (arbeid/overig)","OK")) | AD9: Grammage niet in bestek: frontlit 450 aangenomen
A10: 9 | B10: BÂCHE | C10: Bâche façade Warocqué: L380 x H230 cm, quadri recto UV - Support Frontlit 450 gr - Façonnage ourlets et œillets tous les 30 cm sur les 4 côtés | D10: pièce | E10: 10 | F10: 120 | G10: M02 | H10: 8.74 | K10: M25 | L10: 41 | O10: =IF(G10="","",IF(IFERROR(VLOOKUP(G10,Materialen!$A$2:$I$39,4,0),"")="plaat",Instellingen!$B$4,Instellingen!$B$3)) | P10: =ROUND(N(H10)*IFERROR(IF(VLOOKUP(G10,Materialen!$A$2:$I$39,9,0)="",0,VLOOKUP(G10,Materialen!$A$2:$I$39,9,0)),0)*(1+N(O10))+N(J10)*IFERROR(IF(VLOOKUP(I10,Materialen!$A$2:$I$39,9,0)="",0,VLOOKUP(I10,Materialen!$A$2:$I$39,9,0)),0)*(1+N(O10))+N(L10)*IFERROR(IF(VLOOKUP(K10,Materialen!$A$2:$I$39,9,0)="",0,VLOOKUP(K10,Materialen!$A$2:$I$39,9,0)),0)+N(N10)*IFERROR(IF(VLOOKUP(M10,Materialen!$A$2:$I$39,9,0)="",0,VLOOKUP(M10,Materialen!$A$2:$I$39,9,0)),0),2) | Q10: =IF(G10="",0,IF(IFERROR(VLOOKUP(G10,Materialen!$A$2:$I$39,5,0),"N")="J",ROUND(N(H10)*(1+N(O10))*Instellingen!$B$8,2),0)) | S10: =ROUND(N(R10)/60*Instellingen!$B$9,2) | U10: =P10+Q10+S10+N(T10) | V10: =IF(AC10<>"OK","",F10-U10) | W10: =IF(OR(F10=0,AC10<>"OK"),"",V10/F10) | X10: =IF(N(H10)>0,F10/H10,"") | Y10: =IF(N(H10)>0,IFERROR(IF(VLOOKUP(G10,Materialen!$A$2:$I$39,9,0)="",0,VLOOKUP(G10,Materialen!$A$2:$I$39,9,0)),0),"") | Z10: =ROUND(E10*F10,2) | AA10: =IF(AC10<>"OK","",ROUND(E10*U10,2)) | AB10: =IF(AC10<>"OK","",Z10-AA10) | AC10: =IF((IF(G10="",0,IF(IFERROR(IF(VLOOKUP(G10,Materialen!$A$2:$I$39,9,0)="",0,VLOOKUP(G10,Materialen!$A$2:$I$39,9,0)),0)=0,1,0))+IF(I10="",0,IF(IFERROR(IF(VLOOKUP(I10,Materialen!$A$2:$I$39,9,0)="",0,VLOOKUP(I10,Materialen!$A$2:$I$39,9,0)),0)=0,1,0))+IF(K10="",0,IF(IFERROR(IF(VLOOKUP(K10,Materialen!$A$2:$I$39,9,0)="",0,VLOOKUP(K10,Materialen!$A$2:$I$39,9,0)),0)=0,1,0))+IF(M10="",0,IF(IFERROR(IF(VLOOKUP(M10,Materialen!$A$2:$I$39,9,0)="",0,VLOOKUP(M10,Materialen!$A$2:$I$39,9,0)),0)=0,1,0)))>0,"aankoopprijs ontbreekt",IF(AND(G10="",K10="",N(T10)=0,N(R10)=0),"kost invullen (arbeid/overig)","OK")) | AD10: Oogjes om de 30 cm
A11: 10 | B11: BÂCHE | C11: Bâche pour CUBES: 180 x 180 cm - œillets tous les 30 cm - bâche 330 gr - 10 cm de marge sur chaque côté - 5 mm de bords perdus | D11: pièce | E11: 70 | F11: 42 | G11: M07 | H11: 3.24 | K11: M25 | L11: 24 | O11: =IF(G11="","",IF(IFERROR(VLOOKUP(G11,Materialen!$A$2:$I$39,4,0),"")="plaat",Instellingen!$B$4,Instellingen!$B$3)) | P11: =ROUND(N(H11)*IFERROR(IF(VLOOKUP(G11,Materialen!$A$2:$I$39,9,0)="",0,VLOOKUP(G11,Materialen!$A$2:$I$39,9,0)),0)*(1+N(O11))+N(J11)*IFERROR(IF(VLOOKUP(I11,Materialen!$A$2:$I$39,9,0)="",0,VLOOKUP(I11,Materialen!$A$2:$I$39,9,0)),0)*(1+N(O11))+N(L11)*IFERROR(IF(VLOOKUP(K11,Materialen!$A$2:$I$39,9,0)="",0,VLOOKUP(K11,Materialen!$A$2:$I$39,9,0)),0)+N(N11)*IFERROR(IF(VLOOKUP(M11,Materialen!$A$2:$I$39,9,0)="",0,VLOOKUP(M11,Materialen!$A$2:$I$39,9,0)),0),2) | Q11: =IF(G11="",0,IF(IFERROR(VLOOKUP(G11,Materialen!$A$2:$I$39,5,0),"N")="J",ROUND(N(H11)*(1+N(O11))*Instellingen!$B$8,2),0)) | S11: =ROUND(N(R11)/60*Instellingen!$B$9,2) | U11: =P11+Q11+S11+N(T11) | V11: =IF(AC11<>"OK","",F11-U11) | W11: =IF(OR(F11=0,AC11<>"OK"),"",V11/F11) | X11: =IF(N(H11)>0,F11/H11,"") | Y11: =IF(N(H11)>0,IFERROR(IF(VLOOKUP(G11,Materialen!$A$2:$I$39,9,0)="",0,VLOOKUP(G11,Materialen!$A$2:$I$39,9,0)),0),"") | Z11: =ROUND(E11*F11,2) | AA11: =IF(AC11<>"OK","",ROUND(E11*U11,2)) | AB11: =IF(AC11<>"OK","",Z11-AA11) | AC11: =IF((IF(G11="",0,IF(IFERROR(IF(VLOOKUP(G11,Materialen!$A$2:$I$39,9,0)="",0,VLOOKUP(G11,Materialen!$A$2:$I$39,9,0)),0)=0,1,0))+IF(I11="",0,IF(IFERROR(IF(VLOOKUP(I11,Materialen!$A$2:$I$39,9,0)="",0,VLOOKUP(I11,Materialen!$A$2:$I$39,9,0)),0)=0,1,0))+IF(K11="",0,IF(IFERROR(IF(VLOOKUP(K11,Materialen!$A$2:$I$39,9,0)="",0,VLOOKUP(K11,Materialen!$A$2:$I$39,9,0)),0)=0,1,0))+IF(M11="",0,IF(IFERROR(IF(VLOOKUP(M11,Materialen!$A$2:$I$39,9,0)="",0,VLOOKUP(M11,Materialen!$A$2:$I$39,9,0)),0)=0,1,0)))>0,"aankoopprijs ontbreekt",IF(AND(G11="",K11="",N(T11)=0,N(R11)=0),"kost invullen (arbeid/overig)","OK"))
A12: 11 | B12: BÂCHE | C12: Bâche « cube visitmons » o Format : L105 x H215 cm o Caractéristiques : Bâche Pro 550g, soudure du bord périmètre, œillets tous les 50cm périmètre o Couleurs : impression en quadrichromie | D12: pièce | E12: 90 | F12: 52 | G12: M03 | H12: 2.26 | K12: M25 | L12: 13 | O12: =IF(G12="","",IF(IFERROR(VLOOKUP(G12,Materialen!$A$2:$I$39,4,0),"")="plaat",Instellingen!$B$4,Instellingen!$B$3)) | P12: =ROUND(N(H12)*IFERROR(IF(VLOOKUP(G12,Materialen!$A$2:$I$39,9,0)="",0,VLOOKUP(G12,Materialen!$A$2:$I$39,9,0)),0)*(1+N(O12))+N(J12)*IFERROR(IF(VLOOKUP(I12,Materialen!$A$2:$I$39,9,0)="",0,VLOOKUP(I12,Materialen!$A$2:$I$39,9,0)),0)*(1+N(O12))+N(L12)*IFERROR(IF(VLOOKUP(K12,Materialen!$A$2:$I$39,9,0)="",0,VLOOKUP(K12,Materialen!$A$2:$I$39,9,0)),0)+N(N12)*IFERROR(IF(VLOOKUP(M12,Materialen!$A$2:$I$39,9,0)="",0,VLOOKUP(M12,Materialen!$A$2:$I$39,9,0)),0),2) | Q12: =IF(G12="",0,IF(IFERROR(VLOOKUP(G12,Materialen!$A$2:$I$39,5,0),"N")="J",ROUND(N(H12)*(1+N(O12))*Instellingen!$B$8,2),0)) | S12: =ROUND(N(R12)/60*Instellingen!$B$9,2) | U12: =P12+Q12+S12+N(T12) | V12: =IF(AC12<>"OK","",F12-U12) | W12: =IF(OR(F12=0,AC12<>"OK"),"",V12/F12) | X12: =IF(N(H12)>0,F12/H12,"") | Y12: =IF(N(H12)>0,IFERROR(IF(VLOOKUP(G12,Materialen!$A$2:$I$39,9,0)="",0,VLOOKUP(G12,Materialen!$A$2:$I$39,9,0)),0),"") | Z12: =ROUND(E12*F12,2) | AA12: =IF(AC12<>"OK","",ROUND(E12*U12,2)) | AB12: =IF(AC12<>"OK","",Z12-AA12) | AC12: =IF((IF(G12="",0,IF(IFERROR(IF(VLOOKUP(G12,Materialen!$A$2:$I$39,9,0)="",0,VLOOKUP(G12,Materialen!$A$2:$I$39,9,0)),0)=0,1,0))+IF(I12="",0,IF(IFERROR(IF(VLOOKUP(I12,Materialen!$A$2:$I$39,9,0)="",0,VLOOKUP(I12,Materialen!$A$2:$I$39,9,0)),0)=0,1,0))+IF(K12="",0,IF(IFERROR(IF(VLOOKUP(K12,Materialen!$A$2:$I$39,9,0)="",0,VLOOKUP(K12,Materialen!$A$2:$I$39,9,0)),0)=0,1,0))+IF(M12="",0,IF(IFERROR(IF(VLOOKUP(M12,Materialen!$A$2:$I$39,9,0)="",0,VLOOKUP(M12,Materialen!$A$2:$I$39,9,0)),0)=0,1,0)))>0,"aankoopprijs ontbreekt",IF(AND(G12="",K12="",N(T12)=0,N(R12)=0),"kost invullen (arbeid/overig)","OK"))
A13: 12 | B13: BÂCHE | C13: Bâche barrière « Nadar » o Format : L200xH110cm o Caractéristiques : bâche micro-perforée 290gr avec des œillets tous les 50cm, avec soudure du bord o Couleurs : impression en quadrichromie | D13: pièce | E13: 70 | F13: 38 | G13: M06 | H13: 2.2 | K13: M25 | L13: 13 | O13: =IF(G13="","",IF(IFERROR(VLOOKUP(G13,Materialen!$A$2:$I$39,4,0),"")="plaat",Instellingen!$B$4,Instellingen!$B$3)) | P13: =ROUND(N(H13)*IFERROR(IF(VLOOKUP(G13,Materialen!$A$2:$I$39,9,0)="",0,VLOOKUP(G13,Materialen!$A$2:$I$39,9,0)),0)*(1+N(O13))+N(J13)*IFERROR(IF(VLOOKUP(I13,Materialen!$A$2:$I$39,9,0)="",0,VLOOKUP(I13,Materialen!$A$2:$I$39,9,0)),0)*(1+N(O13))+N(L13)*IFERROR(IF(VLOOKUP(K13,Materialen!$A$2:$I$39,9,0)="",0,VLOOKUP(K13,Materialen!$A$2:$I$39,9,0)),0)+N(N13)*IFERROR(IF(VLOOKUP(M13,Materialen!$A$2:$I$39,9,0)="",0,VLOOKUP(M13,Materialen!$A$2:$I$39,9,0)),0),2) | Q13: =IF(G13="",0,IF(IFERROR(VLOOKUP(G13,Materialen!$A$2:$I$39,5,0),"N")="J",ROUND(N(H13)*(1+N(O13))*Instellingen!$B$8,2),0)) | S13: =ROUND(N(R13)/60*Instellingen!$B$9,2) | U13: =P13+Q13+S13+N(T13) | V13: =IF(AC13<>"OK","",F13-U13) | W13: =IF(OR(F13=0,AC13<>"OK"),"",V13/F13) | X13: =IF(N(H13)>0,F13/H13,"") | Y13: =IF(N(H13)>0,IFERROR(IF(VLOOKUP(G13,Materialen!$A$2:$I$39,9,0)="",0,VLOOKUP(G13,Materialen!$A$2:$I$39,9,0)),0),"") | Z13: =ROUND(E13*F13,2) | AA13: =IF(AC13<>"OK","",ROUND(E13*U13,2)) | AB13: =IF(AC13<>"OK","",Z13-AA13) | AC13: =IF((IF(G13="",0,IF(IFERROR(IF(VLOOKUP(G13,Materialen!$A$2:$I$39,9,0)="",0,VLOOKUP(G13,Materialen!$A$2:$I$39,9,0)),0)=0,1,0))+IF(I13="",0,IF(IFERROR(IF(VLOOKUP(I13,Materialen!$A$2:$I$39,9,0)="",0,VLOOKUP(I13,Materialen!$A$2:$I$39,9,0)),0)=0,1,0))+IF(K13="",0,IF(IFERROR(IF(VLOOKUP(K13,Materialen!$A$2:$I$39,9,0)="",0,VLOOKUP(K13,Materialen!$A$2:$I$39,9,0)),0)=0,1,0))+IF(M13="",0,IF(IFERROR(IF(VLOOKUP(M13,Materialen!$A$2:$I$39,9,0)="",0,VLOOKUP(M13,Materialen!$A$2:$I$39,9,0)),0)=0,1,0)))>0,"aankoopprijs ontbreekt",IF(AND(G13="",K13="",N(T13)=0,N(R13)=0),"kost invullen (arbeid/overig)","OK"))
A14: 13 | B14: ROLLS UP | C14: Rolls up : Format L 85x H 200 cm - Impression quadri recto - sac de transport inclus | D14: pièce | E14: 10 | F14: 78 | G14: M10 | H14: 1.7 | K14: M11 | L14: 1 | O14: =IF(G14="","",IF(IFERROR(VLOOKUP(G14,Materialen!$A$2:$I$39,4,0),"")="plaat",Instellingen!$B$4,Instellingen!$B$3)) | P14: =ROUND(N(H14)*IFERROR(IF(VLOOKUP(G14,Materialen!$A$2:$I$39,9,0)="",0,VLOOKUP(G14,Materialen!$A$2:$I$39,9,0)),0)*(1+N(O14))+N(J14)*IFERROR(IF(VLOOKUP(I14,Materialen!$A$2:$I$39,9,0)="",0,VLOOKUP(I14,Materialen!$A$2:$I$39,9,0)),0)*(1+N(O14))+N(L14)*IFERROR(IF(VLOOKUP(K14,Materialen!$A$2:$I$39,9,0)="",0,VLOOKUP(K14,Materialen!$A$2:$I$39,9,0)),0)+N(N14)*IFERROR(IF(VLOOKUP(M14,Materialen!$A$2:$I$39,9,0)="",0,VLOOKUP(M14,Materialen!$A$2:$I$39,9,0)),0),2) | Q14: =IF(G14="",0,IF(IFERROR(VLOOKUP(G14,Materialen!$A$2:$I$39,5,0),"N")="J",ROUND(N(H14)*(1+N(O14))*Instellingen!$B$8,2),0)) | S14: =ROUND(N(R14)/60*Instellingen!$B$9,2) | U14: =P14+Q14+S14+N(T14) | V14: =IF(AC14<>"OK","",F14-U14) | W14: =IF(OR(F14=0,AC14<>"OK"),"",V14/F14) | X14: =IF(N(H14)>0,F14/H14,"") | Y14: =IF(N(H14)>0,IFERROR(IF(VLOOKUP(G14,Materialen!$A$2:$I$39,9,0)="",0,VLOOKUP(G14,Materialen!$A$2:$I$39,9,0)),0),"") | Z14: =ROUND(E14*F14,2) | AA14: =IF(AC14<>"OK","",ROUND(E14*U14,2)) | AB14: =IF(AC14<>"OK","",Z14-AA14) | AC14: =IF((IF(G14="",0,IF(IFERROR(IF(VLOOKUP(G14,Materialen!$A$2:$I$39,9,0)="",0,VLOOKUP(G14,Materialen!$A$2:$I$39,9,0)),0)=0,1,0))+IF(I14="",0,IF(IFERROR(IF(VLOOKUP(I14,Materialen!$A$2:$I$39,9,0)="",0,VLOOKUP(I14,Materialen!$A$2:$I$39,9,0)),0)=0,1,0))+IF(K14="",0,IF(IFERROR(IF(VLOOKUP(K14,Materialen!$A$2:$I$39,9,0)="",0,VLOOKUP(K14,Materialen!$A$2:$I$39,9,0)),0)=0,1,0))+IF(M14="",0,IF(IFERROR(IF(VLOOKUP(M14,Materialen!$A$2:$I$39,9,0)="",0,VLOOKUP(M14,Materialen!$A$2:$I$39,9,0)),0)=0,1,0)))>0,"aankoopprijs ontbreekt",IF(AND(G14="",K14="",N(T14)=0,N(R14)=0),"kost invullen (arbeid/overig)","OK"))
A15: 14 | B15: ROLLS UP | C15: Rolls up: L60 x H160 cm - Impression quadri recto - Sac de transport inclus | D15: pièce | E15: 10 | F15: 65 | G15: M10 | H15: 0.96 | K15: M12 | L15: 1 | O15: =IF(G15="","",IF(IFERROR(VLOOKUP(G15,Materialen!$A$2:$I$39,4,0),"")="plaat",Instellingen!$B$4,Instellingen!$B$3)) | P15: =ROUND(N(H15)*IFERROR(IF(VLOOKUP(G15,Materialen!$A$2:$I$39,9,0)="",0,VLOOKUP(G15,Materialen!$A$2:$I$39,9,0)),0)*(1+N(O15))+N(J15)*IFERROR(IF(VLOOKUP(I15,Materialen!$A$2:$I$39,9,0)="",0,VLOOKUP(I15,Materialen!$A$2:$I$39,9,0)),0)*(1+N(O15))+N(L15)*IFERROR(IF(VLOOKUP(K15,Materialen!$A$2:$I$39,9,0)="",0,VLOOKUP(K15,Materialen!$A$2:$I$39,9,0)),0)+N(N15)*IFERROR(IF(VLOOKUP(M15,Materialen!$A$2:$I$39,9,0)="",0,VLOOKUP(M15,Materialen!$A$2:$I$39,9,0)),0),2) | Q15: =IF(G15="",0,IF(IFERROR(VLOOKUP(G15,Materialen!$A$2:$I$39,5,0),"N")="J",ROUND(N(H15)*(1+N(O15))*Instellingen!$B$8,2),0)) | S15: =ROUND(N(R15)/60*Instellingen!$B$9,2) | U15: =P15+Q15+S15+N(T15) | V15: =IF(AC15<>"OK","",F15-U15) | W15: =IF(OR(F15=0,AC15<>"OK"),"",V15/F15) | X15: =IF(N(H15)>0,F15/H15,"") | Y15: =IF(N(H15)>0,IFERROR(IF(VLOOKUP(G15,Materialen!$A$2:$I$39,9,0)="",0,VLOOKUP(G15,Materialen!$A$2:$I$39,9,0)),0),"") | Z15: =ROUND(E15*F15,2) | AA15: =IF(AC15<>"OK","",ROUND(E15*U15,2)) | AB15: =IF(AC15<>"OK","",Z15-AA15) | AC15: =IF((IF(G15="",0,IF(IFERROR(IF(VLOOKUP(G15,Materialen!$A$2:$I$39,9,0)="",0,VLOOKUP(G15,Materialen!$A$2:$I$39,9,0)),0)=0,1,0))+IF(I15="",0,IF(IFERROR(IF(VLOOKUP(I15,Materialen!$A$2:$I$39,9,0)="",0,VLOOKUP(I15,Materialen!$A$2:$I$39,9,0)),0)=0,1,0))+IF(K15="",0,IF(IFERROR(IF(VLOOKUP(K15,Materialen!$A$2:$I$39,9,0)="",0,VLOOKUP(K15,Materialen!$A$2:$I$39,9,0)),0)=0,1,0))+IF(M15="",0,IF(IFERROR(IF(VLOOKUP(M15,Materialen!$A$2:$I$39,9,0)="",0,VLOOKUP(M15,Materialen!$A$2:$I$39,9,0)),0)=0,1,0)))>0,"aankoopprijs ontbreekt",IF(AND(G15="",K15="",N(T15)=0,N(R15)=0),"kost invullen (arbeid/overig)","OK"))
A16: 15 | B16: BANNIERE ENTREE ABATTOIRS | C16: Largeur : 75cm (pas de fausse coupe) X Hauteur : 160cm (= format avec ourlet à plat) auxquels on rajoute 10 cm de fausse coupe en haut et en bas et 1,5cm de couture en haut et en bas. Hauteur totale : 183 cm. Impression en quadrichromie | D16: pièce | E16: 10 | F16: 38 | G16: M02 | H16: 1.3725 | O16: =IF(G16="","",IF(IFERROR(VLOOKUP(G16,Materialen!$A$2:$I$39,4,0),"")="plaat",Instellingen!$B$4,Instellingen!$B$3)) | P16: =ROUND(N(H16)*IFERROR(IF(VLOOKUP(G16,Materialen!$A$2:$I$39,9,0)="",0,VLOOKUP(G16,Materialen!$A$2:$I$39,9,0)),0)*(1+N(O16))+N(J16)*IFERROR(IF(VLOOKUP(I16,Materialen!$A$2:$I$39,9,0)="",0,VLOOKUP(I16,Materialen!$A$2:$I$39,9,0)),0)*(1+N(O16))+N(L16)*IFERROR(IF(VLOOKUP(K16,Materialen!$A$2:$I$39,9,0)="",0,VLOOKUP(K16,Materialen!$A$2:$I$39,9,0)),0)+N(N16)*IFERROR(IF(VLOOKUP(M16,Materialen!$A$2:$I$39,9,0)="",0,VLOOKUP(M16,Materialen!$A$2:$I$39,9,0)),0),2) | Q16: =IF(G16="",0,IF(IFERROR(VLOOKUP(G16,Materialen!$A$2:$I$39,5,0),"N")="J",ROUND(N(H16)*(1+N(O16))*Instellingen!$B$8,2),0)) | S16: =ROUND(N(R16)/60*Instellingen!$B$9,2) | U16: =P16+Q16+S16+N(T16) | V16: =IF(AC16<>"OK","",F16-U16) | W16: =IF(OR(F16=0,AC16<>"OK"),"",V16/F16) | X16: =IF(N(H16)>0,F16/H16,"") | Y16: =IF(N(H16)>0,IFERROR(IF(VLOOKUP(G16,Materialen!$A$2:$I$39,9,0)="",0,VLOOKUP(G16,Materialen!$A$2:$I$39,9,0)),0),"") | Z16: =ROUND(E16*F16,2) | AA16: =IF(AC16<>"OK","",ROUND(E16*U16,2)) | AB16: =IF(AC16<>"OK","",Z16-AA16) | AC16: =IF((IF(G16="",0,IF(IFERROR(IF(VLOOKUP(G16,Materialen!$A$2:$I$39,9,0)="",0,VLOOKUP(G16,Materialen!$A$2:$I$39,9,0)),0)=0,1,0))+IF(I16="",0,IF(IFERROR(IF(VLOOKUP(I16,Materialen!$A$2:$I$39,9,0)="",0,VLOOKUP(I16,Materialen!$A$2:$I$39,9,0)),0)=0,1,0))+IF(K16="",0,IF(IFERROR(IF(VLOOKUP(K16,Materialen!$A$2:$I$39,9,0)="",0,VLOOKUP(K16,Materialen!$A$2:$I$39,9,0)),0)=0,1,0))+IF(M16="",0,IF(IFERROR(IF(VLOOKUP(M16,Materialen!$A$2:$I$39,9,0)="",0,VLOOKUP(M16,Materialen!$A$2:$I$39,9,0)),0)=0,1,0)))>0,"aankoopprijs ontbreekt",IF(AND(G16="",K16="",N(T16)=0,N(R16)=0),"kost invullen (arbeid/overig)","OK")) | AD16: Grammage niet in bestek: frontlit 450 aangenomen
A17: 16 | B17: STICKERS | C17: Carré 30x30cm - découpe rectangle carré. Impression en quadrichromie | D17: pièce | E17: 20 | F17: 4.8 | G17: M15 | H17: 0.09 | O17: =IF(G17="","",IF(IFERROR(VLOOKUP(G17,Materialen!$A$2:$I$39,4,0),"")="plaat",Instellingen!$B$4,Instellingen!$B$3)) | P17: =ROUND(N(H17)*IFERROR(IF(VLOOKUP(G17,Materialen!$A$2:$I$39,9,0)="",0,VLOOKUP(G17,Materialen!$A$2:$I$39,9,0)),0)*(1+N(O17))+N(J17)*IFERROR(IF(VLOOKUP(I17,Materialen!$A$2:$I$39,9,0)="",0,VLOOKUP(I17,Materialen!$A$2:$I$39,9,0)),0)*(1+N(O17))+N(L17)*IFERROR(IF(VLOOKUP(K17,Materialen!$A$2:$I$39,9,0)="",0,VLOOKUP(K17,Materialen!$A$2:$I$39,9,0)),0)+N(N17)*IFERROR(IF(VLOOKUP(M17,Materialen!$A$2:$I$39,9,0)="",0,VLOOKUP(M17,Materialen!$A$2:$I$39,9,0)),0),2) | Q17: =IF(G17="",0,IF(IFERROR(VLOOKUP(G17,Materialen!$A$2:$I$39,5,0),"N")="J",ROUND(N(H17)*(1+N(O17))*Instellingen!$B$8,2),0)) | S17: =ROUND(N(R17)/60*Instellingen!$B$9,2) | U17: =P17+Q17+S17+N(T17) | V17: =IF(AC17<>"OK","",F17-U17) | W17: =IF(OR(F17=0,AC17<>"OK"),"",V17/F17) | X17: =IF(N(H17)>0,F17/H17,"") | Y17: =IF(N(H17)>0,IFERROR(IF(VLOOKUP(G17,Materialen!$A$2:$I$39,9,0)="",0,VLOOKUP(G17,Materialen!$A$2:$I$39,9,0)),0),"") | Z17: =ROUND(E17*F17,2) | AA17: =IF(AC17<>"OK","",ROUND(E17*U17,2)) | AB17: =IF(AC17<>"OK","",Z17-AA17) | AC17: =IF((IF(G17="",0,IF(IFERROR(IF(VLOOKUP(G17,Materialen!$A$2:$I$39,9,0)="",0,VLOOKUP(G17,Materialen!$A$2:$I$39,9,0)),0)=0,1,0))+IF(I17="",0,IF(IFERROR(IF(VLOOKUP(I17,Materialen!$A$2:$I$39,9,0)="",0,VLOOKUP(I17,Materialen!$A$2:$I$39,9,0)),0)=0,1,0))+IF(K17="",0,IF(IFERROR(IF(VLOOKUP(K17,Materialen!$A$2:$I$39,9,0)="",0,VLOOKUP(K17,Materialen!$A$2:$I$39,9,0)),0)=0,1,0))+IF(M17="",0,IF(IFERROR(IF(VLOOKUP(M17,Materialen!$A$2:$I$39,9,0)="",0,VLOOKUP(M17,Materialen!$A$2:$I$39,9,0)),0)=0,1,0)))>0,"aankoopprijs ontbreekt",IF(AND(G17="",K17="",N(T17)=0,N(R17)=0),"kost invullen (arbeid/overig)","OK"))
A18: 17 | B18: STICKERS | C18: eletrostatique 15x20cm - quadrichromie miroir et blanc - support sur Vinyle Yupo Taco Jelly | D18: quantité : par 10 | E18: 20 | F18: 18 | G18: M13 | H18: 0.3 | O18: =IF(G18="","",IF(IFERROR(VLOOKUP(G18,Materialen!$A$2:$I$39,4,0),"")="plaat",Instellingen!$B$4,Instellingen!$B$3)) | P18: =ROUND(N(H18)*IFERROR(IF(VLOOKUP(G18,Materialen!$A$2:$I$39,9,0)="",0,VLOOKUP(G18,Materialen!$A$2:$I$39,9,0)),0)*(1+N(O18))+N(J18)*IFERROR(IF(VLOOKUP(I18,Materialen!$A$2:$I$39,9,0)="",0,VLOOKUP(I18,Materialen!$A$2:$I$39,9,0)),0)*(1+N(O18))+N(L18)*IFERROR(IF(VLOOKUP(K18,Materialen!$A$2:$I$39,9,0)="",0,VLOOKUP(K18,Materialen!$A$2:$I$39,9,0)),0)+N(N18)*IFERROR(IF(VLOOKUP(M18,Materialen!$A$2:$I$39,9,0)="",0,VLOOKUP(M18,Materialen!$A$2:$I$39,9,0)),0),2) | Q18: =IF(G18="",0,IF(IFERROR(VLOOKUP(G18,Materialen!$A$2:$I$39,5,0),"N")="J",ROUND(N(H18)*(1+N(O18))*Instellingen!$B$8,2),0)) | S18: =ROUND(N(R18)/60*Instellingen!$B$9,2) | U18: =P18+Q18+S18+N(T18) | V18: =IF(AC18<>"OK","",F18-U18) | W18: =IF(OR(F18=0,AC18<>"OK"),"",V18/F18) | X18: =IF(N(H18)>0,F18/H18,"") | Y18: =IF(N(H18)>0,IFERROR(IF(VLOOKUP(G18,Materialen!$A$2:$I$39,9,0)="",0,VLOOKUP(G18,Materialen!$A$2:$I$39,9,0)),0),"") | Z18: =ROUND(E18*F18,2) | AA18: =IF(AC18<>"OK","",ROUND(E18*U18,2)) | AB18: =IF(AC18<>"OK","",Z18-AA18) | AC18: =IF((IF(G18="",0,IF(IFERROR(IF(VLOOKUP(G18,Materialen!$A$2:$I$39,9,0)="",0,VLOOKUP(G18,Materialen!$A$2:$I$39,9,0)),0)=0,1,0))+IF(I18="",0,IF(IFERROR(IF(VLOOKUP(I18,Materialen!$A$2:$I$39,9,0)="",0,VLOOKUP(I18,Materialen!$A$2:$I$39,9,0)),0)=0,1,0))+IF(K18="",0,IF(IFERROR(IF(VLOOKUP(K18,Materialen!$A$2:$I$39,9,0)="",0,VLOOKUP(K18,Materialen!$A$2:$I$39,9,0)),0)=0,1,0))+IF(M18="",0,IF(IFERROR(IF(VLOOKUP(M18,Materialen!$A$2:$I$39,9,0)="",0,VLOOKUP(M18,Materialen!$A$2:$I$39,9,0)),0)=0,1,0)))>0,"aankoopprijs ontbreekt",IF(AND(G18="",K18="",N(T18)=0,N(R18)=0),"kost invullen (arbeid/overig)","OK")) | AD18: Eenheid = 10 stuks
A19: 18 | B19: STICKERS | C19: 15cm diamètre - quadrichromie miroir + blanc - polymère transparent brillant | D19: quantité : par 10 | E19: 20 | F19: 16 | G19: M14 | H19: 0.177 | O19: =IF(G19="","",IF(IFERROR(VLOOKUP(G19,Materialen!$A$2:$I$39,4,0),"")="plaat",Instellingen!$B$4,Instellingen!$B$3)) | P19: =ROUND(N(H19)*IFERROR(IF(VLOOKUP(G19,Materialen!$A$2:$I$39,9,0)="",0,VLOOKUP(G19,Materialen!$A$2:$I$39,9,0)),0)*(1+N(O19))+N(J19)*IFERROR(IF(VLOOKUP(I19,Materialen!$A$2:$I$39,9,0)="",0,VLOOKUP(I19,Materialen!$A$2:$I$39,9,0)),0)*(1+N(O19))+N(L19)*IFERROR(IF(VLOOKUP(K19,Materialen!$A$2:$I$39,9,0)="",0,VLOOKUP(K19,Materialen!$A$2:$I$39,9,0)),0)+N(N19)*IFERROR(IF(VLOOKUP(M19,Materialen!$A$2:$I$39,9,0)="",0,VLOOKUP(M19,Materialen!$A$2:$I$39,9,0)),0),2) | Q19: =IF(G19="",0,IF(IFERROR(VLOOKUP(G19,Materialen!$A$2:$I$39,5,0),"N")="J",ROUND(N(H19)*(1+N(O19))*Instellingen!$B$8,2),0)) | S19: =ROUND(N(R19)/60*Instellingen!$B$9,2) | U19: =P19+Q19+S19+N(T19) | V19: =IF(AC19<>"OK","",F19-U19) | W19: =IF(OR(F19=0,AC19<>"OK"),"",V19/F19) | X19: =IF(N(H19)>0,F19/H19,"") | Y19: =IF(N(H19)>0,IFERROR(IF(VLOOKUP(G19,Materialen!$A$2:$I$39,9,0)="",0,VLOOKUP(G19,Materialen!$A$2:$I$39,9,0)),0),"") | Z19: =ROUND(E19*F19,2) | AA19: =IF(AC19<>"OK","",ROUND(E19*U19,2)) | AB19: =IF(AC19<>"OK","",Z19-AA19) | AC19: =IF((IF(G19="",0,IF(IFERROR(IF(VLOOKUP(G19,Materialen!$A$2:$I$39,9,0)="",0,VLOOKUP(G19,Materialen!$A$2:$I$39,9,0)),0)=0,1,0))+IF(I19="",0,IF(IFERROR(IF(VLOOKUP(I19,Materialen!$A$2:$I$39,9,0)="",0,VLOOKUP(I19,Materialen!$A$2:$I$39,9,0)),0)=0,1,0))+IF(K19="",0,IF(IFERROR(IF(VLOOKUP(K19,Materialen!$A$2:$I$39,9,0)="",0,VLOOKUP(K19,Materialen!$A$2:$I$39,9,0)),0)=0,1,0))+IF(M19="",0,IF(IFERROR(IF(VLOOKUP(M19,Materialen!$A$2:$I$39,9,0)="",0,VLOOKUP(M19,Materialen!$A$2:$I$39,9,0)),0)=0,1,0)))>0,"aankoopprijs ontbreekt",IF(AND(G19="",K19="",N(T19)=0,N(R19)=0),"kost invullen (arbeid/overig)","OK")) | AD19: Eenheid = 10 stuks; wit onderdruk = extra inkt
A20: 19 | B20: STICKERS | C20: Impression digitale quadri sur autocollant véhicule micro perforé pour vitre | D20: m² | E20: 20 | F20: 38 | G20: M16 | H20: 1 | O20: =IF(G20="","",IF(IFERROR(VLOOKUP(G20,Materialen!$A$2:$I$39,4,0),"")="plaat",Instellingen!$B$4,Instellingen!$B$3)) | P20: =ROUND(N(H20)*IFERROR(IF(VLOOKUP(G20,Materialen!$A$2:$I$39,9,0)="",0,VLOOKUP(G20,Materialen!$A$2:$I$39,9,0)),0)*(1+N(O20))+N(J20)*IFERROR(IF(VLOOKUP(I20,Materialen!$A$2:$I$39,9,0)="",0,VLOOKUP(I20,Materialen!$A$2:$I$39,9,0)),0)*(1+N(O20))+N(L20)*IFERROR(IF(VLOOKUP(K20,Materialen!$A$2:$I$39,9,0)="",0,VLOOKUP(K20,Materialen!$A$2:$I$39,9,0)),0)+N(N20)*IFERROR(IF(VLOOKUP(M20,Materialen!$A$2:$I$39,9,0)="",0,VLOOKUP(M20,Materialen!$A$2:$I$39,9,0)),0),2) | Q20: =IF(G20="",0,IF(IFERROR(VLOOKUP(G20,Materialen!$A$2:$I$39,5,0),"N")="J",ROUND(N(H20)*(1+N(O20))*Instellingen!$B$8,2),0)) | S20: =ROUND(N(R20)/60*Instellingen!$B$9,2) | U20: =P20+Q20+S20+N(T20) | V20: =IF(AC20<>"OK","",F20-U20) | W20: =IF(OR(F20=0,AC20<>"OK"),"",V20/F20) | X20: =IF(N(H20)>0,F20/H20,"") | Y20: =IF(N(H20)>0,IFERROR(IF(VLOOKUP(G20,Materialen!$A$2:$I$39,9,0)="",0,VLOOKUP(G20,Materialen!$A$2:$I$39,9,0)),0),"") | Z20: =ROUND(E20*F20,2) | AA20: =IF(AC20<>"OK","",ROUND(E20*U20,2)) | AB20: =IF(AC20<>"OK","",Z20-AA20) | AC20: =IF((IF(G20="",0,IF(IFERROR(IF(VLOOKUP(G20,Materialen!$A$2:$I$39,9,0)="",0,VLOOKUP(G20,Materialen!$A$2:$I$39,9,0)),0)=0,1,0))+IF(I20="",0,IF(IFERROR(IF(VLOOKUP(I20,Materialen!$A$2:$I$39,9,0)="",0,VLOOKUP(I20,Materialen!$A$2:$I$39,9,0)),0)=0,1,0))+IF(K20="",0,IF(IFERROR(IF(VLOOKUP(K20,Materialen!$A$2:$I$39,9,0)="",0,VLOOKUP(K20,Materialen!$A$2:$I$39,9,0)),0)=0,1,0))+IF(M20="",0,IF(IFERROR(IF(VLOOKUP(M20,Materialen!$A$2:$I$39,9,0)="",0,VLOOKUP(M20,Materialen!$A$2:$I$39,9,0)),0)=0,1,0)))>0,"aankoopprijs ontbreekt",IF(AND(G20="",K20="",N(T20)=0,N(R20)=0),"kost invullen (arbeid/overig)","OK"))
A21: 20 | B21: STICKERS | C21: Impression digitale quadri sur autocollant véhicule pour carrosserie | D21: m² | E21: 10 | F21: 36 | G21: M17 | H21: 1 | O21: =IF(G21="","",IF(IFERROR(VLOOKUP(G21,Materialen!$A$2:$I$39,4,0),"")="plaat",Instellingen!$B$4,Instellingen!$B$3)) | P21: =ROUND(N(H21)*IFERROR(IF(VLOOKUP(G21,Materialen!$A$2:$I$39,9,0)="",0,VLOOKUP(G21,Materialen!$A$2:$I$39,9,0)),0)*(1+N(O21))+N(J21)*IFERROR(IF(VLOOKUP(I21,Materialen!$A$2:$I$39,9,0)="",0,VLOOKUP(I21,Materialen!$A$2:$I$39,9,0)),0)*(1+N(O21))+N(L21)*IFERROR(IF(VLOOKUP(K21,Materialen!$A$2:$I$39,9,0)="",0,VLOOKUP(K21,Materialen!$A$2:$I$39,9,0)),0)+N(N21)*IFERROR(IF(VLOOKUP(M21,Materialen!$A$2:$I$39,9,0)="",0,VLOOKUP(M21,Materialen!$A$2:$I$39,9,0)),0),2) | Q21: =IF(G21="",0,IF(IFERROR(VLOOKUP(G21,Materialen!$A$2:$I$39,5,0),"N")="J",ROUND(N(H21)*(1+N(O21))*Instellingen!$B$8,2),0)) | S21: =ROUND(N(R21)/60*Instellingen!$B$9,2) | U21: =P21+Q21+S21+N(T21) | V21: =IF(AC21<>"OK","",F21-U21) | W21: =IF(OR(F21=0,AC21<>"OK"),"",V21/F21) | X21: =IF(N(H21)>0,F21/H21,"") | Y21: =IF(N(H21)>0,IFERROR(IF(VLOOKUP(G21,Materialen!$A$2:$I$39,9,0)="",0,VLOOKUP(G21,Materialen!$A$2:$I$39,9,0)),0),"") | Z21: =ROUND(E21*F21,2) | AA21: =IF(AC21<>"OK","",ROUND(E21*U21,2)) | AB21: =IF(AC21<>"OK","",Z21-AA21) | AC21: =IF((IF(G21="",0,IF(IFERROR(IF(VLOOKUP(G21,Materialen!$A$2:$I$39,9,0)="",0,VLOOKUP(G21,Materialen!$A$2:$I$39,9,0)),0)=0,1,0))+IF(I21="",0,IF(IFERROR(IF(VLOOKUP(I21,Materialen!$A$2:$I$39,9,0)="",0,VLOOKUP(I21,Materialen!$A$2:$I$39,9,0)),0)=0,1,0))+IF(K21="",0,IF(IFERROR(IF(VLOOKUP(K21,Materialen!$A$2:$I$39,9,0)="",0,VLOOKUP(K21,Materialen!$A$2:$I$39,9,0)),0)=0,1,0))+IF(M21="",0,IF(IFERROR(IF(VLOOKUP(M21,Materialen!$A$2:$I$39,9,0)="",0,VLOOKUP(M21,Materialen!$A$2:$I$39,9,0)),0)=0,1,0)))>0,"aankoopprijs ontbreekt",IF(AND(G21="",K21="",N(T21)=0,N(R21)=0),"kost invullen (arbeid/overig)","OK"))
A22: 21 | B22: STICKERS | C22: Impression digitale quadri sur vinyle autocollant polymère pour extérieur (y compris découpe rectangle) | D22: m² | E22: 30 | F22: 32 | G22: M18 | H22: 1 | O22: =IF(G22="","",IF(IFERROR(VLOOKUP(G22,Materialen!$A$2:$I$39,4,0),"")="plaat",Instellingen!$B$4,Instellingen!$B$3)) | P22: =ROUND(N(H22)*IFERROR(IF(VLOOKUP(G22,Materialen!$A$2:$I$39,9,0)="",0,VLOOKUP(G22,Materialen!$A$2:$I$39,9,0)),0)*(1+N(O22))+N(J22)*IFERROR(IF(VLOOKUP(I22,Materialen!$A$2:$I$39,9,0)="",0,VLOOKUP(I22,Materialen!$A$2:$I$39,9,0)),0)*(1+N(O22))+N(L22)*IFERROR(IF(VLOOKUP(K22,Materialen!$A$2:$I$39,9,0)="",0,VLOOKUP(K22,Materialen!$A$2:$I$39,9,0)),0)+N(N22)*IFERROR(IF(VLOOKUP(M22,Materialen!$A$2:$I$39,9,0)="",0,VLOOKUP(M22,Materialen!$A$2:$I$39,9,0)),0),2) | Q22: =IF(G22="",0,IF(IFERROR(VLOOKUP(G22,Materialen!$A$2:$I$39,5,0),"N")="J",ROUND(N(H22)*(1+N(O22))*Instellingen!$B$8,2),0)) | S22: =ROUND(N(R22)/60*Instellingen!$B$9,2) | U22: =P22+Q22+S22+N(T22) | V22: =IF(AC22<>"OK","",F22-U22) | W22: =IF(OR(F22=0,AC22<>"OK"),"",V22/F22) | X22: =IF(N(H22)>0,F22/H22,"") | Y22: =IF(N(H22)>0,IFERROR(IF(VLOOKUP(G22,Materialen!$A$2:$I$39,9,0)="",0,VLOOKUP(G22,Materialen!$A$2:$I$39,9,0)),0),"") | Z22: =ROUND(E22*F22,2) | AA22: =IF(AC22<>"OK","",ROUND(E22*U22,2)) | AB22: =IF(AC22<>"OK","",Z22-AA22) | AC22: =IF((IF(G22="",0,IF(IFERROR(IF(VLOOKUP(G22,Materialen!$A$2:$I$39,9,0)="",0,VLOOKUP(G22,Materialen!$A$2:$I$39,9,0)),0)=0,1,0))+IF(I22="",0,IF(IFERROR(IF(VLOOKUP(I22,Materialen!$A$2:$I$39,9,0)="",0,VLOOKUP(I22,Materialen!$A$2:$I$39,9,0)),0)=0,1,0))+IF(K22="",0,IF(IFERROR(IF(VLOOKUP(K22,Materialen!$A$2:$I$39,9,0)="",0,VLOOKUP(K22,Materialen!$A$2:$I$39,9,0)),0)=0,1,0))+IF(M22="",0,IF(IFERROR(IF(VLOOKUP(M22,Materialen!$A$2:$I$39,9,0)="",0,VLOOKUP(M22,Materialen!$A$2:$I$39,9,0)),0)=0,1,0)))>0,"aankoopprijs ontbreekt",IF(AND(G22="",K22="",N(T22)=0,N(R22)=0),"kost invullen (arbeid/overig)","OK"))
A23: 22 | B23: STICKERS | C23: Vinyle autocollant pour pose extérieure sur vitrine carré 30x30 cm ou rond 30 cm diamètre impression quadri Quantité : par 10 | D23: pièce | E23: 30 | F23: 48 | G23: M15 | H23: 0.9 | O23: =IF(G23="","",IF(IFERROR(VLOOKUP(G23,Materialen!$A$2:$I$39,4,0),"")="plaat",Instellingen!$B$4,Instellingen!$B$3)) | P23: =ROUND(N(H23)*IFERROR(IF(VLOOKUP(G23,Materialen!$A$2:$I$39,9,0)="",0,VLOOKUP(G23,Materialen!$A$2:$I$39,9,0)),0)*(1+N(O23))+N(J23)*IFERROR(IF(VLOOKUP(I23,Materialen!$A$2:$I$39,9,0)="",0,VLOOKUP(I23,Materialen!$A$2:$I$39,9,0)),0)*(1+N(O23))+N(L23)*IFERROR(IF(VLOOKUP(K23,Materialen!$A$2:$I$39,9,0)="",0,VLOOKUP(K23,Materialen!$A$2:$I$39,9,0)),0)+N(N23)*IFERROR(IF(VLOOKUP(M23,Materialen!$A$2:$I$39,9,0)="",0,VLOOKUP(M23,Materialen!$A$2:$I$39,9,0)),0),2) | Q23: =IF(G23="",0,IF(IFERROR(VLOOKUP(G23,Materialen!$A$2:$I$39,5,0),"N")="J",ROUND(N(H23)*(1+N(O23))*Instellingen!$B$8,2),0)) | S23: =ROUND(N(R23)/60*Instellingen!$B$9,2) | U23: =P23+Q23+S23+N(T23) | V23: =IF(AC23<>"OK","",F23-U23) | W23: =IF(OR(F23=0,AC23<>"OK"),"",V23/F23) | X23: =IF(N(H23)>0,F23/H23,"") | Y23: =IF(N(H23)>0,IFERROR(IF(VLOOKUP(G23,Materialen!$A$2:$I$39,9,0)="",0,VLOOKUP(G23,Materialen!$A$2:$I$39,9,0)),0),"") | Z23: =ROUND(E23*F23,2) | AA23: =IF(AC23<>"OK","",ROUND(E23*U23,2)) | AB23: =IF(AC23<>"OK","",Z23-AA23) | AC23: =IF((IF(G23="",0,IF(IFERROR(IF(VLOOKUP(G23,Materialen!$A$2:$I$39,9,0)="",0,VLOOKUP(G23,Materialen!$A$2:$I$39,9,0)),0)=0,1,0))+IF(I23="",0,IF(IFERROR(IF(VLOOKUP(I23,Materialen!$A$2:$I$39,9,0)="",0,VLOOKUP(I23,Materialen!$A$2:$I$39,9,0)),0)=0,1,0))+IF(K23="",0,IF(IFERROR(IF(VLOOKUP(K23,Materialen!$A$2:$I$39,9,0)="",0,VLOOKUP(K23,Materialen!$A$2:$I$39,9,0)),0)=0,1,0))+IF(M23="",0,IF(IFERROR(IF(VLOOKUP(M23,Materialen!$A$2:$I$39,9,0)="",0,VLOOKUP(M23,Materialen!$A$2:$I$39,9,0)),0)=0,1,0)))>0,"aankoopprijs ontbreekt",IF(AND(G23="",K23="",N(T23)=0,N(R23)=0),"kost invullen (arbeid/overig)","OK")) | AD23: Geprijsd per 10 stuks (zie offerte) – te bevestigen
A24: 23 | B24: STICKERS | C24: Stickers Totem : format 84x199cm - adhésif monomère mat pour le sol - quantité : par 10 | D24: pièce | E24: 45 | F24: 75 | G24: M15 | H24: 1.67 | I24: M19 | J24: 1.67 | O24: =IF(G24="","",IF(IFERROR(VLOOKUP(G24,Materialen!$A$2:$I$39,4,0),"")="plaat",Instellingen!$B$4,Instellingen!$B$3)) | P24: =ROUND(N(H24)*IFERROR(IF(VLOOKUP(G24,Materialen!$A$2:$I$39,9,0)="",0,VLOOKUP(G24,Materialen!$A$2:$I$39,9,0)),0)*(1+N(O24))+N(J24)*IFERROR(IF(VLOOKUP(I24,Materialen!$A$2:$I$39,9,0)="",0,VLOOKUP(I24,Materialen!$A$2:$I$39,9,0)),0)*(1+N(O24))+N(L24)*IFERROR(IF(VLOOKUP(K24,Materialen!$A$2:$I$39,9,0)="",0,VLOOKUP(K24,Materialen!$A$2:$I$39,9,0)),0)+N(N24)*IFERROR(IF(VLOOKUP(M24,Materialen!$A$2:$I$39,9,0)="",0,VLOOKUP(M24,Materialen!$A$2:$I$39,9,0)),0),2) | Q24: =IF(G24="",0,IF(IFERROR(VLOOKUP(G24,Materialen!$A$2:$I$39,5,0),"N")="J",ROUND(N(H24)*(1+N(O24))*Instellingen!$B$8,2),0)) | S24: =ROUND(N(R24)/60*Instellingen!$B$9,2) | U24: =P24+Q24+S24+N(T24) | V24: =IF(AC24<>"OK","",F24-U24) | W24: =IF(OR(F24=0,AC24<>"OK"),"",V24/F24) | X24: =IF(N(H24)>0,F24/H24,"") | Y24: =IF(N(H24)>0,IFERROR(IF(VLOOKUP(G24,Materialen!$A$2:$I$39,9,0)="",0,VLOOKUP(G24,Materialen!$A$2:$I$39,9,0)),0),"") | Z24: =ROUND(E24*F24,2) | AA24: =IF(AC24<>"OK","",ROUND(E24*U24,2)) | AB24: =IF(AC24<>"OK","",Z24-AA24) | AC24: =IF((IF(G24="",0,IF(IFERROR(IF(VLOOKUP(G24,Materialen!$A$2:$I$39,9,0)="",0,VLOOKUP(G24,Materialen!$A$2:$I$39,9,0)),0)=0,1,0))+IF(I24="",0,IF(IFERROR(IF(VLOOKUP(I24,Materialen!$A$2:$I$39,9,0)="",0,VLOOKUP(I24,Materialen!$A$2:$I$39,9,0)),0)=0,1,0))+IF(K24="",0,IF(IFERROR(IF(VLOOKUP(K24,Materialen!$A$2:$I$39,9,0)="",0,VLOOKUP(K24,Materialen!$A$2:$I$39,9,0)),0)=0,1,0))+IF(M24="",0,IF(IFERROR(IF(VLOOKUP(M24,Materialen!$A$2:$I$39,9,0)="",0,VLOOKUP(M24,Materialen!$A$2:$I$39,9,0)),0)=0,1,0)))>0,"aankoopprijs ontbreekt",IF(AND(G24="",K24="",N(T24)=0,N(R24)=0),"kost invullen (arbeid/overig)","OK")) | AD24: Geprijsd per stuk – te bevestigen
A25: 24 | B25: STICKERS | C25: Placement des stickers : prestation pour la pose | D25: pièce | E25: 1 | F25: 55 | O25: =IF(G25="","",IF(IFERROR(VLOOKUP(G25,Materialen!$A$2:$I$39,4,0),"")="plaat",Instellingen!$B$4,Instellingen!$B$3)) | P25: =ROUND(N(H25)*IFERROR(IF(VLOOKUP(G25,Materialen!$A$2:$I$39,9,0)="",0,VLOOKUP(G25,Materialen!$A$2:$I$39,9,0)),0)*(1+N(O25))+N(J25)*IFERROR(IF(VLOOKUP(I25,Materialen!$A$2:$I$39,9,0)="",0,VLOOKUP(I25,Materialen!$A$2:$I$39,9,0)),0)*(1+N(O25))+N(L25)*IFERROR(IF(VLOOKUP(K25,Materialen!$A$2:$I$39,9,0)="",0,VLOOKUP(K25,Materialen!$A$2:$I$39,9,0)),0)+N(N25)*IFERROR(IF(VLOOKUP(M25,Materialen!$A$2:$I$39,9,0)="",0,VLOOKUP(M25,Materialen!$A$2:$I$39,9,0)),0),2) | Q25: =IF(G25="",0,IF(IFERROR(VLOOKUP(G25,Materialen!$A$2:$I$39,5,0),"N")="J",ROUND(N(H25)*(1+N(O25))*Instellingen!$B$8,2),0)) | S25: =ROUND(N(R25)/60*Instellingen!$B$9,2) | U25: =P25+Q25+S25+N(T25) | V25: =IF(AC25<>"OK","",F25-U25) | W25: =IF(OR(F25=0,AC25<>"OK"),"",V25/F25) | X25: =IF(N(H25)>0,F25/H25,"") | Y25: =IF(N(H25)>0,IFERROR(IF(VLOOKUP(G25,Materialen!$A$2:$I$39,9,0)="",0,VLOOKUP(G25,Materialen!$A$2:$I$39,9,0)),0),"") | Z25: =ROUND(E25*F25,2) | AA25: =IF(AC25<>"OK","",ROUND(E25*U25,2)) | AB25: =IF(AC25<>"OK","",Z25-AA25) | AC25: =IF((IF(G25="",0,IF(IFERROR(IF(VLOOKUP(G25,Materialen!$A$2:$I$39,9,0)="",0,VLOOKUP(G25,Materialen!$A$2:$I$39,9,0)),0)=0,1,0))+IF(I25="",0,IF(IFERROR(IF(VLOOKUP(I25,Materialen!$A$2:$I$39,9,0)="",0,VLOOKUP(I25,Materialen!$A$2:$I$39,9,0)),0)=0,1,0))+IF(K25="",0,IF(IFERROR(IF(VLOOKUP(K25,Materialen!$A$2:$I$39,9,0)="",0,VLOOKUP(K25,Materialen!$A$2:$I$39,9,0)),0)=0,1,0))+IF(M25="",0,IF(IFERROR(IF(VLOOKUP(M25,Materialen!$A$2:$I$39,9,0)="",0,VLOOKUP(M25,Materialen!$A$2:$I$39,9,0)),0)=0,1,0)))>0,"aankoopprijs ontbreekt",IF(AND(G25="",K25="",N(T25)=0,N(R25)=0),"kost invullen (arbeid/overig)","OK")) | AD25: Arbeid
A26: 25 | B26: STICKERS | C26: Enlèvement des stickers : prestation de démontage | D26: pièce | E26: 1 | F26: 45 | O26: =IF(G26="","",IF(IFERROR(VLOOKUP(G26,Materialen!$A$2:$I$39,4,0),"")="plaat",Instellingen!$B$4,Instellingen!$B$3)) | P26: =ROUND(N(H26)*IFERROR(IF(VLOOKUP(G26,Materialen!$A$2:$I$39,9,0)="",0,VLOOKUP(G26,Materialen!$A$2:$I$39,9,0)),0)*(1+N(O26))+N(J26)*IFERROR(IF(VLOOKUP(I26,Materialen!$A$2:$I$39,9,0)="",0,VLOOKUP(I26,Materialen!$A$2:$I$39,9,0)),0)*(1+N(O26))+N(L26)*IFERROR(IF(VLOOKUP(K26,Materialen!$A$2:$I$39,9,0)="",0,VLOOKUP(K26,Materialen!$A$2:$I$39,9,0)),0)+N(N26)*IFERROR(IF(VLOOKUP(M26,Materialen!$A$2:$I$39,9,0)="",0,VLOOKUP(M26,Materialen!$A$2:$I$39,9,0)),0),2) | Q26: =IF(G26="",0,IF(IFERROR(VLOOKUP(G26,Materialen!$A$2:$I$39,5,0),"N")="J",ROUND(N(H26)*(1+N(O26))*Instellingen!$B$8,2),0)) | S26: =ROUND(N(R26)/60*Instellingen!$B$9,2) | U26: =P26+Q26+S26+N(T26) | V26: =IF(AC26<>"OK","",F26-U26) | W26: =IF(OR(F26=0,AC26<>"OK"),"",V26/F26) | X26: =IF(N(H26)>0,F26/H26,"") | Y26: =IF(N(H26)>0,IFERROR(IF(VLOOKUP(G26,Materialen!$A$2:$I$39,9,0)="",0,VLOOKUP(G26,Materialen!$A$2:$I$39,9,0)),0),"") | Z26: =ROUND(E26*F26,2) | AA26: =IF(AC26<>"OK","",ROUND(E26*U26,2)) | AB26: =IF(AC26<>"OK","",Z26-AA26) | AC26: =IF((IF(G26="",0,IF(IFERROR(IF(VLOOKUP(G26,Materialen!$A$2:$I$39,9,0)="",0,VLOOKUP(G26,Materialen!$A$2:$I$39,9,0)),0)=0,1,0))+IF(I26="",0,IF(IFERROR(IF(VLOOKUP(I26,Materialen!$A$2:$I$39,9,0)="",0,VLOOKUP(I26,Materialen!$A$2:$I$39,9,0)),0)=0,1,0))+IF(K26="",0,IF(IFERROR(IF(VLOOKUP(K26,Materialen!$A$2:$I$39,9,0)="",0,VLOOKUP(K26,Materialen!$A$2:$I$39,9,0)),0)=0,1,0))+IF(M26="",0,IF(IFERROR(IF(VLOOKUP(M26,Materialen!$A$2:$I$39,9,0)="",0,VLOOKUP(M26,Materialen!$A$2:$I$39,9,0)),0)=0,1,0)))>0,"aankoopprijs ontbreekt",IF(AND(G26="",K26="",N(T26)=0,N(R26)=0),"kost invullen (arbeid/overig)","OK")) | AD26: Arbeid
A27: 26 | B27: BEACH FLAG | C27: Drapeau L 85 x H 260 cm - Hauteur totale avec mât (tube en alu) : 350 cm - Potence horizontale - Toile cousue avec fourreaux vertical et horizontal - Pied en croix - Mousqueton en bas de l'ourlet - Sac de transport | D27: pièce | E27: 20 | F27: 75 | G27: M20 | H27: 2.21 | K27: M21 | L27: 1 | O27: =IF(G27="","",IF(IFERROR(VLOOKUP(G27,Materialen!$A$2:$I$39,4,0),"")="plaat",Instellingen!$B$4,Instellingen!$B$3)) | P27: =ROUND(N(H27)*IFERROR(IF(VLOOKUP(G27,Materialen!$A$2:$I$39,9,0)="",0,VLOOKUP(G27,Materialen!$A$2:$I$39,9,0)),0)*(1+N(O27))+N(J27)*IFERROR(IF(VLOOKUP(I27,Materialen!$A$2:$I$39,9,0)="",0,VLOOKUP(I27,Materialen!$A$2:$I$39,9,0)),0)*(1+N(O27))+N(L27)*IFERROR(IF(VLOOKUP(K27,Materialen!$A$2:$I$39,9,0)="",0,VLOOKUP(K27,Materialen!$A$2:$I$39,9,0)),0)+N(N27)*IFERROR(IF(VLOOKUP(M27,Materialen!$A$2:$I$39,9,0)="",0,VLOOKUP(M27,Materialen!$A$2:$I$39,9,0)),0),2) | Q27: =IF(G27="",0,IF(IFERROR(VLOOKUP(G27,Materialen!$A$2:$I$39,5,0),"N")="J",ROUND(N(H27)*(1+N(O27))*Instellingen!$B$8,2),0)) | S27: =ROUND(N(R27)/60*Instellingen!$B$9,2) | U27: =P27+Q27+S27+N(T27) | V27: =IF(AC27<>"OK","",F27-U27) | W27: =IF(OR(F27=0,AC27<>"OK"),"",V27/F27) | X27: =IF(N(H27)>0,F27/H27,"") | Y27: =IF(N(H27)>0,IFERROR(IF(VLOOKUP(G27,Materialen!$A$2:$I$39,9,0)="",0,VLOOKUP(G27,Materialen!$A$2:$I$39,9,0)),0),"") | Z27: =ROUND(E27*F27,2) | AA27: =IF(AC27<>"OK","",ROUND(E27*U27,2)) | AB27: =IF(AC27<>"OK","",Z27-AA27) | AC27: =IF((IF(G27="",0,IF(IFERROR(IF(VLOOKUP(G27,Materialen!$A$2:$I$39,9,0)="",0,VLOOKUP(G27,Materialen!$A$2:$I$39,9,0)),0)=0,1,0))+IF(I27="",0,IF(IFERROR(IF(VLOOKUP(I27,Materialen!$A$2:$I$39,9,0)="",0,VLOOKUP(I27,Materialen!$A$2:$I$39,9,0)),0)=0,1,0))+IF(K27="",0,IF(IFERROR(IF(VLOOKUP(K27,Materialen!$A$2:$I$39,9,0)="",0,VLOOKUP(K27,Materialen!$A$2:$I$39,9,0)),0)=0,1,0))+IF(M27="",0,IF(IFERROR(IF(VLOOKUP(M27,Materialen!$A$2:$I$39,9,0)="",0,VLOOKUP(M27,Materialen!$A$2:$I$39,9,0)),0)=0,1,0)))>0,"aankoopprijs ontbreekt",IF(AND(G27="",K27="",N(T27)=0,N(R27)=0),"kost invullen (arbeid/overig)","OK"))
